Workbook

Sheet 1-probe_parametric-sxml
A1: SXML Element | B1: XML Attribute | C1: Whole Name | D1: Metadata | E1: STDF Attribute | F1: Name in Yield Metadata Standardization | G1: How to Populate | H1: Index Type | I1: Key/non-key | J1: Data Type | K1: Comment
A2: LotG/SourceLot/Lot | B2: Fab | C2: =IF(NOT(ISBLANK(B2)),_xlfn.CONCAT(A2,"[",B2,"]"),"") -> LotG/SourceLot/Lot[Fab] | D2: =IF(VLOOKUP($C2, Mapping!$C$2:$L$181, 2, FALSE) = 0, "", VLOOKUP($C2, Mapping!$C$2:$L$181, 2, FALSE)) -> Fab | E2: =IF(VLOOKUP($C2, Mapping!$C$2:$L$181, 3, FALSE) = 0, "", VLOOKUP($C2, Mapping!$C$2:$L$181, 3, FALSE)) | F2: =IF(VLOOKUP($C2, Mapping!$C$2:$L$181, 4, FALSE) = 0, "", VLOOKUP($C2, Mapping!$C$2:$L$181, 4, FALSE)) -> Source Fab | G2: =IF(VLOOKUP($C2, Mapping!$C$2:$L$181, 6, FALSE) = 0, "", VLOOKUP($C2, Mapping!$C$2:$L$181, 6, FALSE)) -> vDbFab | H2: =IF(VLOOKUP($C2, Mapping!$C$2:$L$181, 7, FALSE) = 0, "", VLOOKUP($C2, Mapping!$C$2:$L$181, 7, FALSE)) | I2: =IF(VLOOKUP($C2, Mapping!$C$2:$L$181, 8, FALSE) = 0, "", VLOOKUP($C2, Mapping!$C$2:$L$181, 8, FALSE)) | J2: =IF(VLOOKUP($C2, Mapping!$C$2:$L$181, 9, FALSE) = 0, "", VLOOKUP($C2, Mapping!$C$2:$L$181, 9, FALSE)) | K2: =IF(VLOOKUP($C2, Mapping!$C$2:$L$181, 10, FALSE) = 0, "", VLOOKUP($C2, Mapping!$C$2:$L$181, 10, FALSE))
A3: LotG/SourceLot/Lot | B3: LotClass | C3: =IF(NOT(ISBLANK(B3)),_xlfn.CONCAT(A3,"[",B3,"]"),"") -> LotG/SourceLot/Lot[LotClass] | D3: =IF(VLOOKUP($C3, Mapping!$C$2:$L$181, 2, FALSE) = 0, "", VLOOKUP($C3, Mapping!$C$2:$L$181, 2, FALSE)) -> LotClass | E3: =IF(VLOOKUP($C3, Mapping!$C$2:$L$181, 3, FALSE) = 0, "", VLOOKUP($C3, Mapping!$C$2:$L$181, 3, FALSE)) | F3: =IF(VLOOKUP($C3, Mapping!$C$2:$L$181, 4, FALSE) = 0, "", VLOOKUP($C3, Mapping!$C$2:$L$181, 4, FALSE)) -> Lot Class | G3: =IF(VLOOKUP($C3, Mapping!$C$2:$L$181, 6, FALSE) = 0, "", VLOOKUP($C3, Mapping!$C$2:$L$181, 6, FALSE)) -> vDbLotClass | H3: =IF(VLOOKUP($C3, Mapping!$C$2:$L$181, 7, FALSE) = 0, "", VLOOKUP($C3, Mapping!$C$2:$L$181, 7, FALSE)) -> lot class | I3: =IF(VLOOKUP($C3, Mapping!$C$2:$L$181, 8, FALSE) = 0, "", VLOOKUP($C3, Mapping!$C$2:$L$181, 8, FALSE)) | J3: =IF(VLOOKUP($C3, Mapping!$C$2:$L$181, 9, FALSE) = 0, "", VLOOKUP($C3, Mapping!$C$2:$L$181, 9, FALSE)) -> String | K3: =IF(VLOOKUP($C3, Mapping!$C$2:$L$181, 10, FALSE) = 0, "", VLOOKUP($C3, Mapping!$C$2:$L$181, 10, FALSE)) -> LotG or LTM; Type of lot Engineering/Production,…
A4: LotG/SourceLot/Lot | B4: LotNumber | C4: =IF(NOT(ISBLANK(B4)),_xlfn.CONCAT(A4,"[",B4,"]"),"") -> LotG/SourceLot/Lot[LotNumber] | D4: =IF(VLOOKUP($C4, Mapping!$C$2:$L$181, 2, FALSE) = 0, "", VLOOKUP($C4, Mapping!$C$2:$L$181, 2, FALSE)) -> SubconLotId | E4: =IF(VLOOKUP($C4, Mapping!$C$2:$L$181, 3, FALSE) = 0, "", VLOOKUP($C4, Mapping!$C$2:$L$181, 3, FALSE)) | F4: =IF(VLOOKUP($C4, Mapping!$C$2:$L$181, 4, FALSE) = 0, "", VLOOKUP($C4, Mapping!$C$2:$L$181, 4, FALSE)) -> Subcon lot id | G4: =IF(VLOOKUP($C4, Mapping!$C$2:$L$181, 6, FALSE) = 0, "", VLOOKUP($C4, Mapping!$C$2:$L$181, 6, FALSE)) -> DbMetaData("Subcon lot id", vvSubconLotId) | H4: =IF(VLOOKUP($C4, Mapping!$C$2:$L$181, 7, FALSE) = 0, "", VLOOKUP($C4, Mapping!$C$2:$L$181, 7, FALSE)) -> op_log linked index 26 | I4: =IF(VLOOKUP($C4, Mapping!$C$2:$L$181, 8, FALSE) = 0, "", VLOOKUP($C4, Mapping!$C$2:$L$181, 8, FALSE)) | J4: =IF(VLOOKUP($C4, Mapping!$C$2:$L$181, 9, FALSE) = 0, "", VLOOKUP($C4, Mapping!$C$2:$L$181, 9, FALSE)) | K4: =IF(VLOOKUP($C4, Mapping!$C$2:$L$181, 10, FALSE) = 0, "", VLOOKUP($C4, Mapping!$C$2:$L$181, 10, FALSE))
A5: LotG/SourceLot/Lot | B5: WaferPart | C5: =IF(NOT(ISBLANK(B5)),_xlfn.CONCAT(A5,"[",B5,"]"),"") -> LotG/SourceLot/Lot[WaferPart] | D5: =IF(VLOOKUP($C5, Mapping!$C$2:$L$181, 2, FALSE) = 0, "", VLOOKUP($C5, Mapping!$C$2:$L$181, 2, FALSE)) -> Product | E5: =IF(VLOOKUP($C5, Mapping!$C$2:$L$181, 3, FALSE) = 0, "", VLOOKUP($C5, Mapping!$C$2:$L$181, 3, FALSE)) | F5: =IF(VLOOKUP($C5, Mapping!$C$2:$L$181, 4, FALSE) = 0, "", VLOOKUP($C5, Mapping!$C$2:$L$181, 4, FALSE)) -> MES Product ID / Mfg part # | G5: =IF(VLOOKUP($C5, Mapping!$C$2:$L$181, 6, FALSE) = 0, "", VLOOKUP($C5, Mapping!$C$2:$L$181, 6, FALSE)) -> vDbProduct | H5: =IF(VLOOKUP($C5, Mapping!$C$2:$L$181, 7, FALSE) = 0, "", VLOOKUP($C5, Mapping!$C$2:$L$181, 7, FALSE)) | I5: =IF(VLOOKUP($C5, Mapping!$C$2:$L$181, 8, FALSE) = 0, "", VLOOKUP($C5, Mapping!$C$2:$L$181, 8, FALSE)) | J5: =IF(VLOOKUP($C5, Mapping!$C$2:$L$181, 9, FALSE) = 0, "", VLOOKUP($C5, Mapping!$C$2:$L$181, 9, FALSE)) | K5: =IF(VLOOKUP($C5, Mapping!$C$2:$L$181, 10, FALSE) = 0, "", VLOOKUP($C5, Mapping!$C$2:$L$181, 10, FALSE))
A6: LotG/SourceLot/Lot | B6: Bank | C6: =IF(NOT(ISBLANK(B6)),_xlfn.CONCAT(A6,"[",B6,"]"),"") -> LotG/SourceLot/Lot[Bank] | D6: =IF(VLOOKUP($C6, Mapping!$C$2:$L$181, 2, FALSE) = 0, "", VLOOKUP($C6, Mapping!$C$2:$L$181, 2, FALSE)) | E6: =IF(VLOOKUP($C6, Mapping!$C$2:$L$181, 3, FALSE) = 0, "", VLOOKUP($C6, Mapping!$C$2:$L$181, 3, FALSE)) | F6: =IF(VLOOKUP($C6, Mapping!$C$2:$L$181, 4, FALSE) = 0, "", VLOOKUP($C6, Mapping!$C$2:$L$181, 4, FALSE)) -> Bank Lot | G6: =IF(VLOOKUP($C6, Mapping!$C$2:$L$181, 6, FALSE) = 0, "", VLOOKUP($C6, Mapping!$C$2:$L$181, 6, FALSE)) | H6: =IF(VLOOKUP($C6, Mapping!$C$2:$L$181, 7, FALSE) = 0, "", VLOOKUP($C6, Mapping!$C$2:$L$181, 7, FALSE)) | I6: =IF(VLOOKUP($C6, Mapping!$C$2:$L$181, 8, FALSE) = 0, "", VLOOKUP($C6, Mapping!$C$2:$L$181, 8, FALSE)) | J6: =IF(VLOOKUP($C6, Mapping!$C$2:$L$181, 9, FALSE) = 0, "", VLOOKUP($C6, Mapping!$C$2:$L$181, 9, FALSE)) | K6: =IF(VLOOKUP($C6, Mapping!$C$2:$L$181, 10, FALSE) = 0, "", VLOOKUP($C6, Mapping!$C$2:$L$181, 10, FALSE))
A7: DataPort | B7: TestFacility | C7: =IF(NOT(ISBLANK(B7)),_xlfn.CONCAT(A7,"[",B7,"]"),"") -> DataPort[TestFacility] | D7: =IF(VLOOKUP($C7, Mapping!$C$2:$L$181, 2, FALSE) = 0, "", VLOOKUP($C7, Mapping!$C$2:$L$181, 2, FALSE)) -> TestFacility | E7: =IF(VLOOKUP($C7, Mapping!$C$2:$L$181, 3, FALSE) = 0, "", VLOOKUP($C7, Mapping!$C$2:$L$181, 3, FALSE)) | F7: =IF(VLOOKUP($C7, Mapping!$C$2:$L$181, 4, FALSE) = 0, "", VLOOKUP($C7, Mapping!$C$2:$L$181, 4, FALSE)) -> Test Facility | G7: =IF(VLOOKUP($C7, Mapping!$C$2:$L$181, 6, FALSE) = 0, "", VLOOKUP($C7, Mapping!$C$2:$L$181, 6, FALSE)) -> vDbEquip6 | H7: =IF(VLOOKUP($C7, Mapping!$C$2:$L$181, 7, FALSE) = 0, "", VLOOKUP($C7, Mapping!$C$2:$L$181, 7, FALSE)) -> Equip[6] | I7: =IF(VLOOKUP($C7, Mapping!$C$2:$L$181, 8, FALSE) = 0, "", VLOOKUP($C7, Mapping!$C$2:$L$181, 8, FALSE)) | J7: =IF(VLOOKUP($C7, Mapping!$C$2:$L$181, 9, FALSE) = 0, "", VLOOKUP($C7, Mapping!$C$2:$L$181, 9, FALSE)) | K7: =IF(VLOOKUP($C7, Mapping!$C$2:$L$181, 10, FALSE) = 0, "", VLOOKUP($C7, Mapping!$C$2:$L$181, 10, FALSE))
A8: File | B8: FileName | C8: =IF(NOT(ISBLANK(B8)),_xlfn.CONCAT(A8,"[",B8,"]"),"") -> File[FileName] | D8: =IF(VLOOKUP($C8, Mapping!$C$2:$L$181, 2, FALSE) = 0, "", VLOOKUP($C8, Mapping!$C$2:$L$181, 2, FALSE)) -> DataFileName | E8: =IF(VLOOKUP($C8, Mapping!$C$2:$L$181, 3, FALSE) = 0, "", VLOOKUP($C8, Mapping!$C$2:$L$181, 3, FALSE)) | F8: =IF(VLOOKUP($C8, Mapping!$C$2:$L$181, 4, FALSE) = 0, "", VLOOKUP($C8, Mapping!$C$2:$L$181, 4, FALSE)) -> Data File Name | G8: =IF(VLOOKUP($C8, Mapping!$C$2:$L$181, 6, FALSE) = 0, "", VLOOKUP($C8, Mapping!$C$2:$L$181, 6, FALSE)) -> DbMetaData("Data File Name", vFileName) | H8: =IF(VLOOKUP($C8, Mapping!$C$2:$L$181, 7, FALSE) = 0, "", VLOOKUP($C8, Mapping!$C$2:$L$181, 7, FALSE)) -> op_log linked index 3 | I8: =IF(VLOOKUP($C8, Mapping!$C$2:$L$181, 8, FALSE) = 0, "", VLOOKUP($C8, Mapping!$C$2:$L$181, 8, FALSE)) | J8: =IF(VLOOKUP($C8, Mapping!$C$2:$L$181, 9, FALSE) = 0, "", VLOOKUP($C8, Mapping!$C$2:$L$181, 9, FALSE)) | K8: =IF(VLOOKUP($C8, Mapping!$C$2:$L$181, 10, FALSE) = 0, "", VLOOKUP($C8, Mapping!$C$2:$L$181, 10, FALSE))
A9: File/Lot | B9: FinishTime | C9: =IF(NOT(ISBLANK(B9)),_xlfn.CONCAT(A9,"[",B9,"]"),"") -> File/Lot[FinishTime] | D9: =IF(VLOOKUP($C9, Mapping!$C$2:$L$181, 2, FALSE) = 0, "", VLOOKUP($C9, Mapping!$C$2:$L$181, 2, FALSE)) -> EndTime | E9: =IF(VLOOKUP($C9, Mapping!$C$2:$L$181, 3, FALSE) = 0, "", VLOOKUP($C9, Mapping!$C$2:$L$181, 3, FALSE)) -> MRR.FINISH_T | F9: =IF(VLOOKUP($C9, Mapping!$C$2:$L$181, 4, FALSE) = 0, "", VLOOKUP($C9, Mapping!$C$2:$L$181, 4, FALSE)) -> End Time | G9: =IF(VLOOKUP($C9, Mapping!$C$2:$L$181, 6, FALSE) = 0, "", VLOOKUP($C9, Mapping!$C$2:$L$181, 6, FALSE)) -> vDbEndTime | H9: =IF(VLOOKUP($C9, Mapping!$C$2:$L$181, 7, FALSE) = 0, "", VLOOKUP($C9, Mapping!$C$2:$L$181, 7, FALSE)) | I9: =IF(VLOOKUP($C9, Mapping!$C$2:$L$181, 8, FALSE) = 0, "", VLOOKUP($C9, Mapping!$C$2:$L$181, 8, FALSE)) | J9: =IF(VLOOKUP($C9, Mapping!$C$2:$L$181, 9, FALSE) = 0, "", VLOOKUP($C9, Mapping!$C$2:$L$181, 9, FALSE)) | K9: =IF(VLOOKUP($C9, Mapping!$C$2:$L$181, 10, FALSE) = 0, "", VLOOKUP($C9, Mapping!$C$2:$L$181, 10, FALSE))
A10: File/Lot | B10: JobName | C10: =IF(NOT(ISBLANK(B10)),_xlfn.CONCAT(A10,"[",B10,"]"),"") -> File/Lot[JobName] | D10: =IF(VLOOKUP($C10, Mapping!$C$2:$L$181, 2, FALSE) = 0, "", VLOOKUP($C10, Mapping!$C$2:$L$181, 2, FALSE)) -> Recipe | E10: =IF(VLOOKUP($C10, Mapping!$C$2:$L$181, 3, FALSE) = 0, "", VLOOKUP($C10, Mapping!$C$2:$L$181, 3, FALSE)) -> MIR.JOB_NAM | F10: =IF(VLOOKUP($C10, Mapping!$C$2:$L$181, 4, FALSE) = 0, "", VLOOKUP($C10, Mapping!$C$2:$L$181, 4, FALSE)) -> Test Program Name | G10: =IF(VLOOKUP($C10, Mapping!$C$2:$L$181, 6, FALSE) = 0, "", VLOOKUP($C10, Mapping!$C$2:$L$181, 6, FALSE)) -> vDbRecipe | H10: =IF(VLOOKUP($C10, Mapping!$C$2:$L$181, 7, FALSE) = 0, "", VLOOKUP($C10, Mapping!$C$2:$L$181, 7, FALSE)) | I10: =IF(VLOOKUP($C10, Mapping!$C$2:$L$181, 8, FALSE) = 0, "", VLOOKUP($C10, Mapping!$C$2:$L$181, 8, FALSE)) | J10: =IF(VLOOKUP($C10, Mapping!$C$2:$L$181, 9, FALSE) = 0, "", VLOOKUP($C10, Mapping!$C$2:$L$181, 9, FALSE)) | K10: =IF(VLOOKUP($C10, Mapping!$C$2:$L$181, 10, FALSE) = 0, "", VLOOKUP($C10, Mapping!$C$2:$L$181, 10, FALSE))
A11: File/Lot | B11: JobRevision | C11: =IF(NOT(ISBLANK(B11)),_xlfn.CONCAT(A11,"[",B11,"]"),"") -> File/Lot[JobRevision] | D11: =IF(VLOOKUP($C11, Mapping!$C$2:$L$181, 2, FALSE) = 0, "", VLOOKUP($C11, Mapping!$C$2:$L$181, 2, FALSE)) -> RecipeRevision | E11: =IF(VLOOKUP($C11, Mapping!$C$2:$L$181, 3, FALSE) = 0, "", VLOOKUP($C11, Mapping!$C$2:$L$181, 3, FALSE)) -> MIR.JOB_REV | F11: =IF(VLOOKUP($C11, Mapping!$C$2:$L$181, 4, FALSE) = 0, "", VLOOKUP($C11, Mapping!$C$2:$L$181, 4, FALSE)) -> Test Program Revision | G11: =IF(VLOOKUP($C11, Mapping!$C$2:$L$181, 6, FALSE) = 0, "", VLOOKUP($C11, Mapping!$C$2:$L$181, 6, FALSE)) -> vDbEquip5, vDbProgRev | H11: =IF(VLOOKUP($C11, Mapping!$C$2:$L$181, 7, FALSE) = 0, "", VLOOKUP($C11, Mapping!$C$2:$L$181, 7, FALSE)) -> Equip[5] | I11: =IF(VLOOKUP($C11, Mapping!$C$2:$L$181, 8, FALSE) = 0, "", VLOOKUP($C11, Mapping!$C$2:$L$181, 8, FALSE)) | J11: =IF(VLOOKUP($C11, Mapping!$C$2:$L$181, 9, FALSE) = 0, "", VLOOKUP($C11, Mapping!$C$2:$L$181, 9, FALSE)) | K11: =IF(VLOOKUP($C11, Mapping!$C$2:$L$181, 10, FALSE) = 0, "", VLOOKUP($C11, Mapping!$C$2:$L$181, 10, FALSE))
A12: File/Lot | B12: LotId | C12: =IF(NOT(ISBLANK(B12)),_xlfn.CONCAT(A12,"[",B12,"]"),"") -> File/Lot[LotId] | D12: =IF(VLOOKUP($C12, Mapping!$C$2:$L$181, 2, FALSE) = 0, "", VLOOKUP($C12, Mapping!$C$2:$L$181, 2, FALSE)) -> LotId | E12: =IF(VLOOKUP($C12, Mapping!$C$2:$L$181, 3, FALSE) = 0, "", VLOOKUP($C12, Mapping!$C$2:$L$181, 3, FALSE)) -> MIR.LOT_ID | F12: =IF(VLOOKUP($C12, Mapping!$C$2:$L$181, 4, FALSE) = 0, "", VLOOKUP($C12, Mapping!$C$2:$L$181, 4, FALSE)) -> Lot ID | G12: =IF(VLOOKUP($C12, Mapping!$C$2:$L$181, 6, FALSE) = 0, "", VLOOKUP($C12, Mapping!$C$2:$L$181, 6, FALSE)) -> vDbLot | H12: =IF(VLOOKUP($C12, Mapping!$C$2:$L$181, 7, FALSE) = 0, "", VLOOKUP($C12, Mapping!$C$2:$L$181, 7, FALSE)) | I12: =IF(VLOOKUP($C12, Mapping!$C$2:$L$181, 8, FALSE) = 0, "", VLOOKUP($C12, Mapping!$C$2:$L$181, 8, FALSE)) | J12: =IF(VLOOKUP($C12, Mapping!$C$2:$L$181, 9, FALSE) = 0, "", VLOOKUP($C12, Mapping!$C$2:$L$181, 9, FALSE)) | K12: =IF(VLOOKUP($C12, Mapping!$C$2:$L$181, 10, FALSE) = 0, "", VLOOKUP($C12, Mapping!$C$2:$L$181, 10, FALSE))
A13: File/Lot | B13: ModeCode | C13: =IF(NOT(ISBLANK(B13)),_xlfn.CONCAT(A13,"[",B13,"]"),"") -> File/Lot[ModeCode] | D13: =IF(VLOOKUP($C13, Mapping!$C$2:$L$181, 2, FALSE) = 0, "", VLOOKUP($C13, Mapping!$C$2:$L$181, 2, FALSE)) | E13: =IF(VLOOKUP($C13, Mapping!$C$2:$L$181, 3, FALSE) = 0, "", VLOOKUP($C13, Mapping!$C$2:$L$181, 3, FALSE)) -> MIR.MODE_COD | F13: =IF(VLOOKUP($C13, Mapping!$C$2:$L$181, 4, FALSE) = 0, "", VLOOKUP($C13, Mapping!$C$2:$L$181, 4, FALSE)) | G13: =IF(VLOOKUP($C13, Mapping!$C$2:$L$181, 6, FALSE) = 0, "", VLOOKUP($C13, Mapping!$C$2:$L$181, 6, FALSE)) | H13: =IF(VLOOKUP($C13, Mapping!$C$2:$L$181, 7, FALSE) = 0, "", VLOOKUP($C13, Mapping!$C$2:$L$181, 7, FALSE)) | I13: =IF(VLOOKUP($C13, Mapping!$C$2:$L$181, 8, FALSE) = 0, "", VLOOKUP($C13, Mapping!$C$2:$L$181, 8, FALSE)) | J13: =IF(VLOOKUP($C13, Mapping!$C$2:$L$181, 9, FALSE) = 0, "", VLOOKUP($C13, Mapping!$C$2:$L$181, 9, FALSE)) | K13: =IF(VLOOKUP($C13, Mapping!$C$2:$L$181, 10, FALSE) = 0, "", VLOOKUP($C13, Mapping!$C$2:$L$181, 10, FALSE))
... A33: File/Lot/Wafer/ParametricData/Unit | B33: Site | C33: =IF(NOT(ISBLANK(B33)),_xlfn.CONCAT(A33,"[",B33,"]"),"") -> File/Lot/Wafer/ParametricData/Unit[Site] | D33: =IF(VLOOKUP($C33, Mapping!$C$2:$L$181, 2, FALSE) = 0, "", VLOOKUP($C33, Mapping!$C$2:$L$181, 2, FALSE)) | E33: =IF(VLOOKUP($C33, Mapping!$C$2:$L$181, 3, FALSE) = 0, "", VLOOKUP($C33, Mapping!$C$2:$L$181, 3, FALSE)) | F33: =IF(VLOOKUP($C33, Mapping!$C$2:$L$181, 4, FALSE) = 0, "", VLOOKUP($C33, Mapping!$C$2:$L$181, 4, FALSE)) -> Test Site ID | G33: =IF(VLOOKUP($C33, Mapping!$C$2:$L$181, 6, FALSE) = 0, "", VLOOKUP($C33, Mapping!$C$2:$L$181, 6, FALSE)) -> TestSite (Index) | H33: =IF(VLOOKUP($C33, Mapping!$C$2:$L$181, 7, FALSE) = 0, "", VLOOKUP($C33, Mapping!$C$2:$L$181, 7, FALSE)) | I33: =IF(VLOOKUP($C33, Mapping!$C$2:$L$181, 8, FALSE) = 0, "", VLOOKUP($C33, Mapping!$C$2:$L$181, 8, FALSE)) | J33: =IF(VLOOKUP($C33, Mapping!$C$2:$L$181, 9, FALSE) = 0, "", VLOOKUP($C33, Mapping!$C$2:$L$181, 9, FALSE)) | K33: =IF(VLOOKUP($C33, Mapping!$C$2:$L$181, 10, FALSE) = 0, "", VLOOKUP($C33, Mapping!$C$2:$L$181, 10, FALSE))
B34: Program Group | C34: =IF(NOT(ISBLANK(B34)),_xlfn.CONCAT(A34,"[",B34,"]"),"") -> [Program Group] | D34: =IF(VLOOKUP($C34, Mapping!$C$2:$L$181, 2, FALSE) = 0, "", VLOOKUP($C34, Mapping!$C$2:$L$181, 2, FALSE)) -> ProgramGroup | E34: =IF(VLOOKUP($C34, Mapping!$C$2:$L$181, 3, FALSE) = 0, "", VLOOKUP($C34, Mapping!$C$2:$L$181, 3, FALSE)) | F34: =IF(VLOOKUP($C34, Mapping!$C$2:$L$181, 4, FALSE) = 0, "", VLOOKUP($C34, Mapping!$C$2:$L$181, 4, FALSE)) -> Program Group | G34: =IF(VLOOKUP($C34, Mapping!$C$2:$L$181, 6, FALSE) = 0, "", VLOOKUP($C34, Mapping!$C$2:$L$181, 6, FALSE)) -> vDbProgGroup | H34: =IF(VLOOKUP($C34, Mapping!$C$2:$L$181, 7, FALSE) = 0, "", VLOOKUP($C34, Mapping!$C$2:$L$181, 7, FALSE)) | I34: =IF(VLOOKUP($C34, Mapping!$C$2:$L$181, 8, FALSE) = 0, "", VLOOKUP($C34, Mapping!$C$2:$L$181, 8, FALSE)) | J34: =IF(VLOOKUP($C34, Mapping!$C$2:$L$181, 9, FALSE) = 0, "", VLOOKUP($C34, Mapping!$C$2:$L$181, 9, FALSE)) | K34: =IF(VLOOKUP($C34, Mapping!$C$2:$L$181, 10, FALSE) = 0, "", VLOOKUP($C34, Mapping!$C$2:$L$181, 10, FALSE)) -> Constant: "Probe Parametric"
B35: Area | C35: =IF(NOT(ISBLANK(B35)),_xlfn.CONCAT(A35,"[",B35,"]"),"") -> [Area] | D35: =IF(VLOOKUP($C35, Mapping!$C$2:$L$181, 2, FALSE) = 0, "", VLOOKUP($C35, Mapping!$C$2:$L$181, 2, FALSE)) | E35: =IF(VLOOKUP($C35, Mapping!$C$2:$L$181, 3, FALSE) = 0, "", VLOOKUP($C35, Mapping!$C$2:$L$181, 3, FALSE)) | F35: =IF(VLOOKUP($C35, Mapping!$C$2:$L$181, 4, FALSE) = 0, "", VLOOKUP($C35, Mapping!$C$2:$L$181, 4, FALSE)) -> Area | G35: =IF(VLOOKUP($C35, Mapping!$C$2:$L$181, 6, FALSE) = 0, "", VLOOKUP($C35, Mapping!$C$2:$L$181, 6, FALSE)) -> DbMetaData("Area", vArea) | H35: =IF(VLOOKUP($C35, Mapping!$C$2:$L$181, 7, FALSE) = 0, "", VLOOKUP($C35, Mapping!$C$2:$L$181, 7, FALSE)) -> op_log linked index 1 | I35: =IF(VLOOKUP($C35, Mapping!$C$2:$L$181, 8, FALSE) = 0, "", VLOOKUP($C35, Mapping!$C$2:$L$181, 8, FALSE)) | J35: =IF(VLOOKUP($C35, Mapping!$C$2:$L$181, 9, FALSE) = 0, "", VLOOKUP($C35, Mapping!$C$2:$L$181, 9, FALSE)) | K35: =IF(VLOOKUP($C35, Mapping!$C$2:$L$181, 10, FALSE) = 0, "", VLOOKUP($C35, Mapping!$C$2:$L$181, 10, FALSE)) -> Constant: "Probe"
B36: Reticle Id | C36: =IF(NOT(ISBLANK(B36)),_xlfn.CONCAT(A36,"[",B36,"]"),"") -> [Reticle Id] | D36: =IF(VLOOKUP($C36, Mapping!$C$2:$L$181, 2, FALSE) = 0, "", VLOOKUP($C36, Mapping!$C$2:$L$181, 2, FALSE)) | E36: =IF(VLOOKUP($C36, Mapping!$C$2:$L$181, 3, FALSE) = 0, "", VLOOKUP($C36, Mapping!$C$2:$L$181, 3, FALSE)) | F36: =IF(VLOOKUP($C36, Mapping!$C$2:$L$181, 4, FALSE) = 0, "", VLOOKUP($C36, Mapping!$C$2:$L$181, 4, FALSE)) -> reticle_id | G36: =IF(VLOOKUP($C36, Mapping!$C$2:$L$181, 6, FALSE) = 0, "", VLOOKUP($C36, Mapping!$C$2:$L$181, 6, FALSE)) -> (Index) | H36: =IF(VLOOKUP($C36, Mapping!$C$2:$L$181, 7, FALSE) = 0, "", VLOOKUP($C36, Mapping!$C$2:$L$181, 7, FALSE)) -> res index | I36: =IF(VLOOKUP($C36, Mapping!$C$2:$L$181, 8, FALSE) = 0, "", VLOOKUP($C36, Mapping!$C$2:$L$181, 8, FALSE)) -> non-key | J36: =IF(VLOOKUP($C36, Mapping!$C$2:$L$181, 9, FALSE) = 0, "", VLOOKUP($C36, Mapping!$C$2:$L$181, 9, FALSE)) -> String | K36: =IF(VLOOKUP($C36, Mapping!$C$2:$L$181, 10, FALSE) = 0, "", VLOOKUP($C36, Mapping!$C$2:$L$181, 10, FALSE)) -> Set to -1 by default if reticle coordinates are not available.
A37: File/Lot | B37: Tester/Tool ID | C37: =IF(NOT(ISBLANK(B37)),_xlfn.CONCAT(A37,"[",B37,"]"),"") -> File/Lot[Tester/Tool ID] | D37: =IF(VLOOKUP($C37, Mapping!$C$2:$L$181, 2, FALSE) = 0, "", VLOOKUP($C37, Mapping!$C$2:$L$181, 2, FALSE)) -> MeasuringEquipment | E37: =IF(VLOOKUP($C37, Mapping!$C$2:$L$181, 3, FALSE) = 0, "", VLOOKUP($C37, Mapping!$C$2:$L$181, 3, FALSE)) | F37: =IF(VLOOKUP($C37, Mapping!$C$2:$L$181, 4, FALSE) = 0, "", VLOOKUP($C37, Mapping!$C$2:$L$181, 4, FALSE)) -> Tester/Tool ID | G37: =IF(VLOOKUP($C37, Mapping!$C$2:$L$181, 6, FALSE) = 0, "", VLOOKUP($C37, Mapping!$C$2:$L$181, 6, FALSE)) -> vDbEquip1 | H37: =IF(VLOOKUP($C37, Mapping!$C$2:$L$181, 7, FALSE) = 0, "", VLOOKUP($C37, Mapping!$C$2:$L$181, 7, FALSE)) -> Equip[1] | I37: =IF(VLOOKUP($C37, Mapping!$C$2:$L$181, 8, FALSE) = 0, "", VLOOKUP($C37, Mapping!$C$2:$L$181, 8, FALSE)) | J37: =IF(VLOOKUP($C37, Mapping!$C$2:$L$181, 9, FALSE) = 0, "", VLOOKUP($C37, Mapping!$C$2:$L$181, 9, FALSE)) | K37: =IF(VLOOKUP($C37, Mapping!$C$2:$L$181, 10, FALSE) = 0, "", VLOOKUP($C37, Mapping!$C$2:$L$181, 10, FALSE))
A38: File/Lot/Sites/Site | B38: HandlerId | C38: =IF(NOT(ISBLANK(B38)),_xlfn.CONCAT(A38,"[",B38,"]"),"") -> File/Lot/Sites/Site[HandlerId] | D38: =IF(VLOOKUP($C38, Mapping!$C$2:$L$181, 2, FALSE) = 0, "", VLOOKUP($C38, Mapping!$C$2:$L$181, 2, FALSE)) | E38: =IF(VLOOKUP($C38, Mapping!$C$2:$L$181, 3, FALSE) = 0, "", VLOOKUP($C38, Mapping!$C$2:$L$181, 3, FALSE)) -> SDR.HAND_ID | F38: =IF(VLOOKUP($C38, Mapping!$C$2:$L$181, 4, FALSE) = 0, "", VLOOKUP($C38, Mapping!$C$2:$L$181, 4, FALSE)) -> Prober ID | G38: =IF(VLOOKUP($C38, Mapping!$C$2:$L$181, 6, FALSE) = 0, "", VLOOKUP($C38, Mapping!$C$2:$L$181, 6, FALSE)) -> vDbEquip2 | H38: =IF(VLOOKUP($C38, Mapping!$C$2:$L$181, 7, FALSE) = 0, "", VLOOKUP($C38, Mapping!$C$2:$L$181, 7, FALSE)) -> Equip[2] | I38: =IF(VLOOKUP($C38, Mapping!$C$2:$L$181, 8, FALSE) = 0, "", VLOOKUP($C38, Mapping!$C$2:$L$181, 8, FALSE)) | J38: =IF(VLOOKUP($C38, Mapping!$C$2:$L$181, 9, FALSE) = 0, "", VLOOKUP($C38, Mapping!$C$2:$L$181, 9, FALSE)) | K38: =IF(VLOOKUP($C38, Mapping!$C$2:$L$181, 10, FALSE) = 0, "", VLOOKUP($C38, Mapping!$C$2:$L$181, 10, FALSE))
B39: Probe ID Type | C39: =IF(NOT(ISBLANK(B39)),_xlfn.CONCAT(A39,"[",B39,"]"),"") -> [Probe ID Type] | D39: =IF(VLOOKUP($C39, Mapping!$C$2:$L$181, 2, FALSE) = 0, "", VLOOKUP($C39, Mapping!$C$2:$L$181, 2, FALSE)) | E39: =IF(VLOOKUP($C39, Mapping!$C$2:$L$181, 3, FALSE) = 0, "", VLOOKUP($C39, Mapping!$C$2:$L$181, 3, FALSE)) -> SDR.HAND_TYP | F39: =IF(VLOOKUP($C39, Mapping!$C$2:$L$181, 4, FALSE) = 0, "", VLOOKUP($C39, Mapping!$C$2:$L$181, 4, FALSE)) -> Prober ID Type | G39: =IF(VLOOKUP($C39, Mapping!$C$2:$L$181, 6, FALSE) = 0, "", VLOOKUP($C39, Mapping!$C$2:$L$181, 6, FALSE)) | H39: =IF(VLOOKUP($C39, Mapping!$C$2:$L$181, 7, FALSE) = 0, "", VLOOKUP($C39, Mapping!$C$2:$L$181, 7, FALSE)) -> Equip[2] Type | I39: =IF(VLOOKUP($C39, Mapping!$C$2:$L$181, 8, FALSE) = 0, "", VLOOKUP($C39, Mapping!$C$2:$L$181, 8, FALSE)) | J39: =IF(VLOOKUP($C39, Mapping!$C$2:$L$181, 9, FALSE) = 0, "", VLOOKUP($C39, Mapping!$C$2:$L$181, 9, FALSE)) | K39: =IF(VLOOKUP($C39, Mapping!$C$2:$L$181, 10, FALSE) = 0, "", VLOOKUP($C39, Mapping!$C$2:$L$181, 10, FALSE))
A40: File/Lot/Sites/Site | B40: CardId | C40: =IF(NOT(ISBLANK(B40)),_xlfn.CONCAT(A40,"[",B40,"]"),"") -> File/Lot/Sites/Site[CardId] | D40: =IF(VLOOKUP($C40, Mapping!$C$2:$L$181, 2, FALSE) = 0, "", VLOOKUP($C40, Mapping!$C$2:$L$181, 2, FALSE)) | E40: =IF(VLOOKUP($C40, Mapping!$C$2:$L$181, 3, FALSE) = 0, "", VLOOKUP($C40, Mapping!$C$2:$L$181, 3, FALSE)) -> SDR.CARD_ID | F40: =IF(VLOOKUP($C40, Mapping!$C$2:$L$181, 4, FALSE) = 0, "", VLOOKUP($C40, Mapping!$C$2:$L$181, 4, FALSE)) -> Probe Card | G40: =IF(VLOOKUP($C40, Mapping!$C$2:$L$181, 6, FALSE) = 0, "", VLOOKUP($C40, Mapping!$C$2:$L$181, 6, FALSE)) -> vDbEquip3 | H40: =IF(VLOOKUP($C40, Mapping!$C$2:$L$181, 7, FALSE) = 0, "", VLOOKUP($C40, Mapping!$C$2:$L$181, 7, FALSE)) -> Equip[3] | I40: =IF(VLOOKUP($C40, Mapping!$C$2:$L$181, 8, FALSE) = 0, "", VLOOKUP($C40, Mapping!$C$2:$L$181, 8, FALSE)) | J40: =IF(VLOOKUP($C40, Mapping!$C$2:$L$181, 9, FALSE) = 0, "", VLOOKUP($C40, Mapping!$C$2:$L$181, 9, FALSE)) | K40: =IF(VLOOKUP($C40, Mapping!$C$2:$L$181, 10, FALSE) = 0, "", VLOOKUP($C40, Mapping!$C$2:$L$181, 10, FALSE))
B41: Probe Card Type | C41: =IF(NOT(ISBLANK(B41)),_xlfn.CONCAT(A41,"[",B41,"]"),"") -> [Probe Card Type] | D41: =IF(VLOOKUP($C41, Mapping!$C$2:$L$181, 2, FALSE) = 0, "", VLOOKUP($C41, Mapping!$C$2:$L$181, 2, FALSE)) | E41: =IF(VLOOKUP($C41, Mapping!$C$2:$L$181, 3, FALSE) = 0, "", VLOOKUP($C41, Mapping!$C$2:$L$181, 3, FALSE)) -> SDR.CARD_TYP | F41: =IF(VLOOKUP($C41, Mapping!$C$2:$L$181, 4, FALSE) = 0, "", VLOOKUP($C41, Mapping!$C$2:$L$181, 4, FALSE)) -> Probe Card Type | G41: =IF(VLOOKUP($C41, Mapping!$C$2:$L$181, 6, FALSE) = 0, "", VLOOKUP($C41, Mapping!$C$2:$L$181, 6, FALSE)) | H41: =IF(VLOOKUP($C41, Mapping!$C$2:$L$181, 7, FALSE) = 0, "", VLOOKUP($C41, Mapping!$C$2:$L$181, 7, FALSE)) -> Equip[3] Type | I41: =IF(VLOOKUP($C41, Mapping!$C$2:$L$181, 8, FALSE) = 0, "", VLOOKUP($C41, Mapping!$C$2:$L$181, 8, FALSE)) | J41: =IF(VLOOKUP($C41, Mapping!$C$2:$L$181, 9, FALSE) = 0, "", VLOOKUP($C41, Mapping!$C$2:$L$181, 9, FALSE)) | K41: =IF(VLOOKUP($C41, Mapping!$C$2:$L$181, 10, FALSE) = 0, "", VLOOKUP($C41, Mapping!$C$2:$L$181, 10, FALSE))
A42: DwPlm | B42: PAL4_CD | C42: =IF(NOT(ISBLANK(B42)),_xlfn.CONCAT(A42,"[",B42,"]"),"") -> DwPlm[PAL4_CD] | D42: =IF(VLOOKUP($C42, Mapping!$C$2:$L$181, 2, FALSE) = 0, "", VLOOKUP($C42, Mapping!$C$2:$L$181, 2, FALSE)) -> Pti4Pal | E42: =IF(VLOOKUP($C42, Mapping!$C$2:$L$181, 3, FALSE) = 0, "", VLOOKUP($C42, Mapping!$C$2:$L$181, 3, FALSE)) | F42: =IF(VLOOKUP($C42, Mapping!$C$2:$L$181, 4, FALSE) = 0, "", VLOOKUP($C42, Mapping!$C$2:$L$181, 4, FALSE)) -> PTI4/PAL | G42: =IF(VLOOKUP($C42, Mapping!$C$2:$L$181, 6, FALSE) = 0, "", VLOOKUP($C42, Mapping!$C$2:$L$181, 6, FALSE)) -> DbMetaData("PTI4/PAL", vPti4Pal) | H42: =IF(VLOOKUP($C42, Mapping!$C$2:$L$181, 7, FALSE) = 0, "", VLOOKUP($C42, Mapping!$C$2:$L$181, 7, FALSE)) -> op_log linked index 4 | I42: =IF(VLOOKUP($C42, Mapping!$C$2:$L$181, 8, FALSE) = 0, "", VLOOKUP($C42, Mapping!$C$2:$L$181, 8, FALSE)) | J42: =IF(VLOOKUP($C42, Mapping!$C$2:$L$181, 9, FALSE) = 0, "", VLOOKUP($C42, Mapping!$C$2:$L$181, 9, FALSE)) | K42: =IF(VLOOKUP($C42, Mapping!$C$2:$L$181, 10, FALSE) = 0, "", VLOOKUP($C42, Mapping!$C$2:$L$181, 10, FALSE)) -> LotG or Agile; Eric
A43: DwPlm | B43: WFR_FAB_MASK_CONFIG_ID | C43: =IF(NOT(ISBLANK(B43)),_xlfn.CONCAT(A43,"[",B43,"]"),"") -> DwPlm[WFR_FAB_MASK_CONFIG_ID] | D43: =IF(VLOOKUP($C43, Mapping!$C$2:$L$181, 2, FALSE) = 0, "", VLOOKUP($C43, Mapping!$C$2:$L$181, 2, FALSE)) -> MaskSet | E43: =IF(VLOOKUP($C43, Mapping!$C$2:$L$181, 3, FALSE) = 0, "", VLOOKUP($C43, Mapping!$C$2:$L$181, 3, FALSE)) | F43: =IF(VLOOKUP($C43, Mapping!$C$2:$L$181, 4, FALSE) = 0, "", VLOOKUP($C43, Mapping!$C$2:$L$181, 4, FALSE)) -> Mask / Mask Set | G43: =IF(VLOOKUP($C43, Mapping!$C$2:$L$181, 6, FALSE) = 0, "", VLOOKUP($C43, Mapping!$C$2:$L$181, 6, FALSE)) -> DbMetaData("Mask / Mask Set", vMaskMaskSet) | H43: =IF(VLOOKUP($C43, Mapping!$C$2:$L$181, 7, FALSE) = 0, "", VLOOKUP($C43, Mapping!$C$2:$L$181, 7, FALSE)) -> op_log linked index 21 | I43: =IF(VLOOKUP($C43, Mapping!$C$2:$L$181, 8, FALSE) = 0, "", VLOOKUP($C43, Mapping!$C$2:$L$181, 8, FALSE)) | J43: =IF(VLOOKUP($C43, Mapping!$C$2:$L$181, 9, FALSE) = 0, "", VLOOKUP($C43, Mapping!$C$2:$L$181, 9, FALSE)) | K43: =IF(VLOOKUP($C43, Mapping!$C$2:$L$181, 10, FALSE) = 0, "", VLOOKUP($C43, Mapping!$C$2:$L$181, 10, FALSE)) -> LotG or Agile; Eric
A44: DwPlm | B44: WFR_TECH_VARIANT_ID | C44: =IF(NOT(ISBLANK(B44)),_xlfn.CONCAT(A44,"[",B44,"]"),"") -> DwPlm[WFR_TECH_VARIANT_ID] | D44: =IF(VLOOKUP($C44, Mapping!$C$2:$L$181, 2, FALSE) = 0, "", VLOOKUP($C44, Mapping!$C$2:$L$181, 2, FALSE)) -> ProcessFamily | E44: =IF(VLOOKUP($C44, Mapping!$C$2:$L$181, 3, FALSE) = 0, "", VLOOKUP($C44, Mapping!$C$2:$L$181, 3, FALSE)) | F44: =IF(VLOOKUP($C44, Mapping!$C$2:$L$181, 4, FALSE) = 0, "", VLOOKUP($C44, Mapping!$C$2:$L$181, 4, FALSE)) -> Process Family | G44: =IF(VLOOKUP($C44, Mapping!$C$2:$L$181, 6, FALSE) = 0, "", VLOOKUP($C44, Mapping!$C$2:$L$181, 6, FALSE)) -> DbMetaData("Process Family", vProcessFamily) | H44: =IF(VLOOKUP($C44, Mapping!$C$2:$L$181, 7, FALSE) = 0, "", VLOOKUP($C44, Mapping!$C$2:$L$181, 7, FALSE)) -> op_log linked index 22 | I44: =IF(VLOOKUP($C44, Mapping!$C$2:$L$181, 8, FALSE) = 0, "", VLOOKUP($C44, Mapping!$C$2:$L$181, 8, FALSE)) | J44: =IF(VLOOKUP($C44, Mapping!$C$2:$L$181, 9, FALSE) = 0, "", VLOOKUP($C44, Mapping!$C$2:$L$181, 9, FALSE)) | K44: =IF(VLOOKUP($C44, Mapping!$C$2:$L$181, 10, FALSE) = 0, "", VLOOKUP($C44, Mapping!$C$2:$L$181, 10, FALSE)) -> LotG or Agile; Eric
B45: Test Head | C45: =IF(NOT(ISBLANK(B45)),_xlfn.CONCAT(A45,"[",B45,"]"),"") -> [Test Head] | D45: =IF(VLOOKUP($C45, Mapping!$C$2:$L$181, 2, FALSE) = 0, "", VLOOKUP($C45, Mapping!$C$2:$L$181, 2, FALSE)) -> TestHead | E45: =IF(VLOOKUP($C45, Mapping!$C$2:$L$181, 3, FALSE) = 0, "", VLOOKUP($C45, Mapping!$C$2:$L$181, 3, FALSE)) | F45: =IF(VLOOKUP($C45, Mapping!$C$2:$L$181, 4, FALSE) = 0, "", VLOOKUP($C45, Mapping!$C$2:$L$181, 4, FALSE)) -> Test Head | G45: =IF(VLOOKUP($C45, Mapping!$C$2:$L$181, 6, FALSE) = 0, "", VLOOKUP($C45, Mapping!$C$2:$L$181, 6, FALSE)) -> DbMetaData("Test Head", vTest Head) | H45: =IF(VLOOKUP($C45, Mapping!$C$2:$L$181, 7, FALSE) = 0, "", VLOOKUP($C45, Mapping!$C$2:$L$181, 7, FALSE)) -> op_log linked index 23 | I45: =IF(VLOOKUP($C45, Mapping!$C$2:$L$181, 8, FALSE) = 0, "", VLOOKUP($C45, Mapping!$C$2:$L$181, 8, FALSE)) | J45: =IF(VLOOKUP($C45, Mapping!$C$2:$L$181, 9, FALSE) = 0, "", VLOOKUP($C45, Mapping!$C$2:$L$181, 9, FALSE)) | K45: =IF(VLOOKUP($C45, Mapping!$C$2:$L$181, 10, FALSE) = 0, "", VLOOKUP($C45, Mapping!$C$2:$L$181, 10, FALSE))
A46: DwPlm | B46: WFR_FAB_MASK | C46: =IF(NOT(ISBLANK(B46)),_xlfn.CONCAT(A46,"[",B46,"]"),"") -> DwPlm[WFR_FAB_MASK] | D46: =IF(VLOOKUP($C46, Mapping!$C$2:$L$181, 2, FALSE) = 0, "", VLOOKUP($C46, Mapping!$C$2:$L$181, 2, FALSE)) -> ProductCode | E46: =IF(VLOOKUP($C46, Mapping!$C$2:$L$181, 3, FALSE) = 0, "", VLOOKUP($C46, Mapping!$C$2:$L$181, 3, FALSE)) | F46: =IF(VLOOKUP($C46, Mapping!$C$2:$L$181, 4, FALSE) = 0, "", VLOOKUP($C46, Mapping!$C$2:$L$181, 4, FALSE)) -> Product Code | G46: =IF(VLOOKUP($C46, Mapping!$C$2:$L$181, 6, FALSE) = 0, "", VLOOKUP($C46, Mapping!$C$2:$L$181, 6, FALSE)) -> DbMetaData("Product Code", vProductCode) | H46: =IF(VLOOKUP($C46, Mapping!$C$2:$L$181, 7, FALSE) = 0, "", VLOOKUP($C46, Mapping!$C$2:$L$181, 7, FALSE)) -> op_log linked index 24 | I46: =IF(VLOOKUP($C46, Mapping!$C$2:$L$181, 8, FALSE) = 0, "", VLOOKUP($C46, Mapping!$C$2:$L$181, 8, FALSE)) | J46: =IF(VLOOKUP($C46, Mapping!$C$2:$L$181, 9, FALSE) = 0, "", VLOOKUP($C46, Mapping!$C$2:$L$181, 9, FALSE)) | K46: =IF(VLOOKUP($C46, Mapping!$C$2:$L$181, 10, FALSE) = 0, "", VLOOKUP($C46, Mapping!$C$2:$L$181, 10, FALSE)) -> LotG or Agile; Firs 4 chars of WFR_FAB_MASK_CONFIG_ID + : + PART_ID
B47: Card Lens Module | C47: =IF(NOT(ISBLANK(B47)),_xlfn.CONCAT(A47,"[",B47,"]"),"") -> [Card Lens Module] | D47: =IF(VLOOKUP($C47, Mapping!$C$2:$L$181, 2, FALSE) = 0, "", VLOOKUP($C47, Mapping!$C$2:$L$181, 2, FALSE)) | E47: =IF(VLOOKUP($C47, Mapping!$C$2:$L$181, 3, FALSE) = 0, "", VLOOKUP($C47, Mapping!$C$2:$L$181, 3, FALSE)) | F47: =IF(VLOOKUP($C47, Mapping!$C$2:$L$181, 4, FALSE) = 0, "", VLOOKUP($C47, Mapping!$C$2:$L$181, 4, FALSE)) -> Card Lens Module | G47: =IF(VLOOKUP($C47, Mapping!$C$2:$L$181, 6, FALSE) = 0, "", VLOOKUP($C47, Mapping!$C$2:$L$181, 6, FALSE)) -> DbMetaData("Card Lens Module", vCardLensModule) | H47: =IF(VLOOKUP($C47, Mapping!$C$2:$L$181, 7, FALSE) = 0, "", VLOOKUP($C47, Mapping!$C$2:$L$181, 7, FALSE)) -> op_log linked index 25 | I47: =IF(VLOOKUP($C47, Mapping!$C$2:$L$181, 8, FALSE) = 0, "", VLOOKUP($C47, Mapping!$C$2:$L$181, 8, FALSE)) | J47: =IF(VLOOKUP($C47, Mapping!$C$2:$L$181, 9, FALSE) = 0, "", VLOOKUP($C47, Mapping!$C$2:$L$181, 9, FALSE)) | K47: =IF(VLOOKUP($C47, Mapping!$C$2:$L$181, 10, FALSE) = 0, "", VLOOKUP($C47, Mapping!$C$2:$L$181, 10, FALSE)) -> NULL, ISG specific
B48: Subcon Product | C48: =IF(NOT(ISBLANK(B48)),_xlfn.CONCAT(A48,"[",B48,"]"),"") -> [Subcon Product] | D48: =IF(VLOOKUP($C48, Mapping!$C$2:$L$181, 2, FALSE) = 0, "", VLOOKUP($C48, Mapping!$C$2:$L$181, 2, FALSE)) -> SubconProduct | E48: =IF(VLOOKUP($C48, Mapping!$C$2:$L$181, 3, FALSE) = 0, "", VLOOKUP($C48, Mapping!$C$2:$L$181, 3, FALSE)) | F48: =IF(VLOOKUP($C48, Mapping!$C$2:$L$181, 4, FALSE) = 0, "", VLOOKUP($C48, Mapping!$C$2:$L$181, 4, FALSE)) -> Subcon Product | G48: =IF(VLOOKUP($C48, Mapping!$C$2:$L$181, 6, FALSE) = 0, "", VLOOKUP($C48, Mapping!$C$2:$L$181, 6, FALSE)) -> DbMetaData("Subcon Product", vSubconProduct) | H48: =IF(VLOOKUP($C48, Mapping!$C$2:$L$181, 7, FALSE) = 0, "", VLOOKUP($C48, Mapping!$C$2:$L$181, 7, FALSE)) -> op_log linked index 27 | I48: =IF(VLOOKUP($C48, Mapping!$C$2:$L$181, 8, FALSE) = 0, "", VLOOKUP($C48, Mapping!$C$2:$L$181, 8, FALSE)) | J48: =IF(VLOOKUP($C48, Mapping!$C$2:$L$181, 9, FALSE) = 0, "", VLOOKUP($C48, Mapping!$C$2:$L$181, 9, FALSE)) | K48: =IF(VLOOKUP($C48, Mapping!$C$2:$L$181, 10, FALSE) = 0, "", VLOOKUP($C48, Mapping!$C$2:$L$181, 10, FALSE))
B49: Serial/Sequence Number | C49: =IF(NOT(ISBLANK(B49)),_xlfn.CONCAT(A49,"[",B49,"]"),"") -> [Serial/Sequence Number] | D49: =IF(VLOOKUP($C49, Mapping!$C$2:$L$181, 2, FALSE) = 0, "", VLOOKUP($C49, Mapping!$C$2:$L$181, 2, FALSE)) | E49: =IF(VLOOKUP($C49, Mapping!$C$2:$L$181, 3, FALSE) = 0, "", VLOOKUP($C49, Mapping!$C$2:$L$181, 3, FALSE)) -> PRR | F49: =IF(VLOOKUP($C49, Mapping!$C$2:$L$181, 4, FALSE) = 0, "", VLOOKUP($C49, Mapping!$C$2:$L$181, 4, FALSE)) -> Serial/Sequence Number | G49: =IF(VLOOKUP($C49, Mapping!$C$2:$L$181, 6, FALSE) = 0, "", VLOOKUP($C49, Mapping!$C$2:$L$181, 6, FALSE)) -> die_index | H49: =IF(VLOOKUP($C49, Mapping!$C$2:$L$181, 7, FALSE) = 0, "", VLOOKUP($C49, Mapping!$C$2:$L$181, 7, FALSE)) -> res index | I49: =IF(VLOOKUP($C49, Mapping!$C$2:$L$181, 8, FALSE) = 0, "", VLOOKUP($C49, Mapping!$C$2:$L$181, 8, FALSE)) -> key | J49: =IF(VLOOKUP($C49, Mapping!$C$2:$L$181, 9, FALSE) = 0, "", VLOOKUP($C49, Mapping!$C$2:$L$181, 9, FALSE)) -> Integer | K49: =IF(VLOOKUP($C49, Mapping!$C$2:$L$181, 10, FALSE) = 0, "", VLOOKUP($C49, Mapping!$C$2:$L$181, 10, FALSE))
B50: ECID | C50: =IF(NOT(ISBLANK(B50)),_xlfn.CONCAT(A50,"[",B50,"]"),"") -> [ECID] | D50: =IF(VLOOKUP($C50, Mapping!$C$2:$L$181, 2, FALSE) = 0, "", VLOOKUP($C50, Mapping!$C$2:$L$181, 2, FALSE)) | E50: =IF(VLOOKUP($C50, Mapping!$C$2:$L$181, 3, FALSE) = 0, "", VLOOKUP($C50, Mapping!$C$2:$L$181, 3, FALSE)) | F50: =IF(VLOOKUP($C50, Mapping!$C$2:$L$181, 4, FALSE) = 0, "", VLOOKUP($C50, Mapping!$C$2:$L$181, 4, FALSE)) -> ECID | G50: =IF(VLOOKUP($C50, Mapping!$C$2:$L$181, 6, FALSE) = 0, "", VLOOKUP($C50, Mapping!$C$2:$L$181, 6, FALSE)) -> ecid | H50: =IF(VLOOKUP($C50, Mapping!$C$2:$L$181, 7, FALSE) = 0, "", VLOOKUP($C50, Mapping!$C$2:$L$181, 7, FALSE)) -> res index | I50: =IF(VLOOKUP($C50, Mapping!$C$2:$L$181, 8, FALSE) = 0, "", VLOOKUP($C50, Mapping!$C$2:$L$181, 8, FALSE)) -> key | J50: =IF(VLOOKUP($C50, Mapping!$C$2:$L$181, 9, FALSE) = 0, "", VLOOKUP($C50, Mapping!$C$2:$L$181, 9, FALSE)) -> String | K50: =IF(VLOOKUP($C50, Mapping!$C$2:$L$181, 10, FALSE) = 0, "", VLOOKUP($C50, Mapping!$C$2:$L$181, 10, FALSE)) -> If no die ID or ECID present in data file, create a "virtual ID" uniquely identifying the die/PART. Probe or wafer/frame/ring-level final test: "lotId_WaferNumber:x#:y#"; "LD595A_12:x45:y-6" Module or sub assembly level test: "lot-id:module-id" (this scenario is unlikely because the unique module ID will be passed into the IFF as a unique serial #/ECID) Singulated final test: "lot-id:serial-number" Call DbDieIdIndex() to establish to activate DLT
B51: Part Pass/Fail Flag (from tester) | C51: =IF(NOT(ISBLANK(B51)),_xlfn.CONCAT(A51,"[",B51,"]"),"") -> [Part Pass/Fail Flag (from tester)] | D51: =IF(VLOOKUP($C51, Mapping!$C$2:$L$181, 2, FALSE) = 0, "", VLOOKUP($C51, Mapping!$C$2:$L$181, 2, FALSE)) | E51: =IF(VLOOKUP($C51, Mapping!$C$2:$L$181, 3, FALSE) = 0, "", VLOOKUP($C51, Mapping!$C$2:$L$181, 3, FALSE)) | F51: =IF(VLOOKUP($C51, Mapping!$C$2:$L$181, 4, FALSE) = 0, "", VLOOKUP($C51, Mapping!$C$2:$L$181, 4, FALSE)) -> Part Pass/Fail Flag (from tester) | G51: =IF(VLOOKUP($C51, Mapping!$C$2:$L$181, 6, FALSE) = 0, "", VLOOKUP($C51, Mapping!$C$2:$L$181, 6, FALSE)) -> pass_or_fail | H51: =IF(VLOOKUP($C51, Mapping!$C$2:$L$181, 7, FALSE) = 0, "", VLOOKUP($C51, Mapping!$C$2:$L$181, 7, FALSE)) -> res index | I51: =IF(VLOOKUP($C51, Mapping!$C$2:$L$181, 8, FALSE) = 0, "", VLOOKUP($C51, Mapping!$C$2:$L$181, 8, FALSE)) -> non-key | J51: =IF(VLOOKUP($C51, Mapping!$C$2:$L$181, 9, FALSE) = 0, "", VLOOKUP($C51, Mapping!$C$2:$L$181, 9, FALSE)) -> String | K51: =IF(VLOOKUP($C51, Mapping!$C$2:$L$181, 10, FALSE) = 0, "", VLOOKUP($C51, Mapping!$C$2:$L$181, 10, FALSE)) -> Bin Pass/Fail Flag
B52: Test Execution Time | C52: =IF(NOT(ISBLANK(B52)),_xlfn.CONCAT(A52,"[",B52,"]"),"") -> [Test Execution Time] | D52: =IF(VLOOKUP($C52, Mapping!$C$2:$L$181, 2, FALSE) = 0, "", VLOOKUP($C52, Mapping!$C$2:$L$181, 2, FALSE)) | E52: =IF(VLOOKUP($C52, Mapping!$C$2:$L$181, 3, FALSE) = 0, "", VLOOKUP($C52, Mapping!$C$2:$L$181, 3, FALSE)) -> PRR.TEST_T | F52: =IF(VLOOKUP($C52, Mapping!$C$2:$L$181, 4, FALSE) = 0, "", VLOOKUP($C52, Mapping!$C$2:$L$181, 4, FALSE)) -> Test Execution Time | G52: =IF(VLOOKUP($C52, Mapping!$C$2:$L$181, 6, FALSE) = 0, "", VLOOKUP($C52, Mapping!$C$2:$L$181, 6, FALSE)) | H52: =IF(VLOOKUP($C52, Mapping!$C$2:$L$181, 7, FALSE) = 0, "", VLOOKUP($C52, Mapping!$C$2:$L$181, 7, FALSE)) -> parameter | I52: =IF(VLOOKUP($C52, Mapping!$C$2:$L$181, 8, FALSE) = 0, "", VLOOKUP($C52, Mapping!$C$2:$L$181, 8, FALSE)) | J52: =IF(VLOOKUP($C52, Mapping!$C$2:$L$181, 9, FALSE) = 0, "", VLOOKUP($C52, Mapping!$C$2:$L$181, 9, FALSE)) | K52: =IF(VLOOKUP($C52, Mapping!$C$2:$L$181, 10, FALSE) = 0, "", VLOOKUP($C52, Mapping!$C$2:$L$181, 10, FALSE)) -> Set To -1
B53: BinDesc | C53: =IF(NOT(ISBLANK(B53)),_xlfn.CONCAT(A53,"[",B53,"]"),"") -> [BinDesc] | D53: =IF(VLOOKUP($C53, Mapping!$C$2:$L$181, 2, FALSE) = 0, "", VLOOKUP($C53, Mapping!$C$2:$L$181, 2, FALSE)) | E53: =IF(VLOOKUP($C53, Mapping!$C$2:$L$181, 3, FALSE) = 0, "", VLOOKUP($C53, Mapping!$C$2:$L$181, 3, FALSE)) -> SBR.BIN_NAME | F53: =IF(VLOOKUP($C53, Mapping!$C$2:$L$181, 4, FALSE) = 0, "", VLOOKUP($C53, Mapping!$C$2:$L$181, 4, FALSE)) -> BinDesc | G53: =IF(VLOOKUP($C53, Mapping!$C$2:$L$181, 6, FALSE) = 0, "", VLOOKUP($C53, Mapping!$C$2:$L$181, 6, FALSE)) -> bindesc | H53: =IF(VLOOKUP($C53, Mapping!$C$2:$L$181, 7, FALSE) = 0, "", VLOOKUP($C53, Mapping!$C$2:$L$181, 7, FALSE)) -> res index | I53: =IF(VLOOKUP($C53, Mapping!$C$2:$L$181, 8, FALSE) = 0, "", VLOOKUP($C53, Mapping!$C$2:$L$181, 8, FALSE)) -> non-key | J53: =IF(VLOOKUP($C53, Mapping!$C$2:$L$181, 9, FALSE) = 0, "", VLOOKUP($C53, Mapping!$C$2:$L$181, 9, FALSE)) -> String | K53: =IF(VLOOKUP($C53, Mapping!$C$2:$L$181, 10, FALSE) = 0, "", VLOOKUP($C53, Mapping!$C$2:$L$181, 10, FALSE))
B54: orig_x | C54: =IF(NOT(ISBLANK(B54)),_xlfn.CONCAT(A54,"[",B54,"]"),"") -> [orig_x] | D54: =IF(VLOOKUP($C54, Mapping!$C$2:$L$181, 2, FALSE) = 0, "", VLOOKUP($C54, Mapping!$C$2:$L$181, 2, FALSE)) | E54: =IF(VLOOKUP($C54, Mapping!$C$2:$L$181, 3, FALSE) = 0, "", VLOOKUP($C54, Mapping!$C$2:$L$181, 3, FALSE)) | F54: =IF(VLOOKUP($C54, Mapping!$C$2:$L$181, 4, FALSE) = 0, "", VLOOKUP($C54, Mapping!$C$2:$L$181, 4, FALSE)) -> orig_x | G54: =IF(VLOOKUP($C54, Mapping!$C$2:$L$181, 6, FALSE) = 0, "", VLOOKUP($C54, Mapping!$C$2:$L$181, 6, FALSE)) -> orig_x | H54: =IF(VLOOKUP($C54, Mapping!$C$2:$L$181, 7, FALSE) = 0, "", VLOOKUP($C54, Mapping!$C$2:$L$181, 7, FALSE)) -> res index | I54: =IF(VLOOKUP($C54, Mapping!$C$2:$L$181, 8, FALSE) = 0, "", VLOOKUP($C54, Mapping!$C$2:$L$181, 8, FALSE)) -> non-key | J54: =IF(VLOOKUP($C54, Mapping!$C$2:$L$181, 9, FALSE) = 0, "", VLOOKUP($C54, Mapping!$C$2:$L$181, 9, FALSE)) -> Integer | K54: =IF(VLOOKUP($C54, Mapping!$C$2:$L$181, 10, FALSE) = 0, "", VLOOKUP($C54, Mapping!$C$2:$L$181, 10, FALSE)) -> Same as die_x, die_y, do NOT call DbDieXYIndexes for these. Used to retain original X,Y after normalization.
B55: orig_y | C55: =IF(NOT(ISBLANK(B55)),_xlfn.CONCAT(A55,"[",B55,"]"),"") -> [orig_y] | D55: =IF(VLOOKUP($C55, Mapping!$C$2:$L$181, 2, FALSE) = 0, "", VLOOKUP($C55, Mapping!$C$2:$L$181, 2, FALSE)) | E55: =IF(VLOOKUP($C55, Mapping!$C$2:$L$181, 3, FALSE) = 0, "", VLOOKUP($C55, Mapping!$C$2:$L$181, 3, FALSE)) | F55: =IF(VLOOKUP($C55, Mapping!$C$2:$L$181, 4, FALSE) = 0, "", VLOOKUP($C55, Mapping!$C$2:$L$181, 4, FALSE)) -> orig_y | G55: =IF(VLOOKUP($C55, Mapping!$C$2:$L$181, 6, FALSE) = 0, "", VLOOKUP($C55, Mapping!$C$2:$L$181, 6, FALSE)) -> orig_y | H55: =IF(VLOOKUP($C55, Mapping!$C$2:$L$181, 7, FALSE) = 0, "", VLOOKUP($C55, Mapping!$C$2:$L$181, 7, FALSE)) -> res index | I55: =IF(VLOOKUP($C55, Mapping!$C$2:$L$181, 8, FALSE) = 0, "", VLOOKUP($C55, Mapping!$C$2:$L$181, 8, FALSE)) -> non-key | J55: =IF(VLOOKUP($C55, Mapping!$C$2:$L$181, 9, FALSE) = 0, "", VLOOKUP($C55, Mapping!$C$2:$L$181, 9, FALSE)) -> Integer | K55: =IF(VLOOKUP($C55, Mapping!$C$2:$L$181, 10, FALSE) = 0, "", VLOOKUP($C55, Mapping!$C$2:$L$181, 10, FALSE)) -> Same as die_x, die_y, do NOT call DbDieXYIndexes for these. Used to retain original X,Y after normalization.
B56: reticle_x | C56: =IF(NOT(ISBLANK(B56)),_xlfn.CONCAT(A56,"[",B56,"]"),"") -> [reticle_x] | D56: =IF(VLOOKUP($C56, Mapping!$C$2:$L$181, 2, FALSE) = 0, "", VLOOKUP($C56, Mapping!$C$2:$L$181, 2, FALSE)) | E56: =IF(VLOOKUP($C56, Mapping!$C$2:$L$181, 3, FALSE) = 0, "", VLOOKUP($C56, Mapping!$C$2:$L$181, 3, FALSE)) | F56: =IF(VLOOKUP($C56, Mapping!$C$2:$L$181, 4, FALSE) = 0, "", VLOOKUP($C56, Mapping!$C$2:$L$181, 4, FALSE)) -> reticle_x | G56: =IF(VLOOKUP($C56, Mapping!$C$2:$L$181, 6, FALSE) = 0, "", VLOOKUP($C56, Mapping!$C$2:$L$181, 6, FALSE)) -> reticle_x | H56: =IF(VLOOKUP($C56, Mapping!$C$2:$L$181, 7, FALSE) = 0, "", VLOOKUP($C56, Mapping!$C$2:$L$181, 7, FALSE)) -> res index | I56: =IF(VLOOKUP($C56, Mapping!$C$2:$L$181, 8, FALSE) = 0, "", VLOOKUP($C56, Mapping!$C$2:$L$181, 8, FALSE)) -> non-key | J56: =IF(VLOOKUP($C56, Mapping!$C$2:$L$181, 9, FALSE) = 0, "", VLOOKUP($C56, Mapping!$C$2:$L$181, 9, FALSE)) -> Integer | K56: =IF(VLOOKUP($C56, Mapping!$C$2:$L$181, 10, FALSE) = 0, "", VLOOKUP($C56, Mapping!$C$2:$L$181, 10, FALSE)) -> Set to -1 by default if intra-reticle coordinates not available.
B57: recitcle_y | C57: =IF(NOT(ISBLANK(B57)),_xlfn.CONCAT(A57,"[",B57,"]"),"") -> [recitcle_y] | D57: =IF(VLOOKUP($C57, Mapping!$C$2:$L$181, 2, FALSE) = 0, "", VLOOKUP($C57, Mapping!$C$2:$L$181, 2, FALSE)) | E57: =IF(VLOOKUP($C57, Mapping!$C$2:$L$181, 3, FALSE) = 0, "", VLOOKUP($C57, Mapping!$C$2:$L$181, 3, FALSE)) | F57: =IF(VLOOKUP($C57, Mapping!$C$2:$L$181, 4, FALSE) = 0, "", VLOOKUP($C57, Mapping!$C$2:$L$181, 4, FALSE)) -> recitcle_y | G57: =IF(VLOOKUP($C57, Mapping!$C$2:$L$181, 6, FALSE) = 0, "", VLOOKUP($C57, Mapping!$C$2:$L$181, 6, FALSE)) -> recitcle_y | H57: =IF(VLOOKUP($C57, Mapping!$C$2:$L$181, 7, FALSE) = 0, "", VLOOKUP($C57, Mapping!$C$2:$L$181, 7, FALSE)) -> res index | I57: =IF(VLOOKUP($C57, Mapping!$C$2:$L$181, 8, FALSE) = 0, "", VLOOKUP($C57, Mapping!$C$2:$L$181, 8, FALSE)) -> non-key | J57: =IF(VLOOKUP($C57, Mapping!$C$2:$L$181, 9, FALSE) = 0, "", VLOOKUP($C57, Mapping!$C$2:$L$181, 9, FALSE)) -> Integer | K57: =IF(VLOOKUP($C57, Mapping!$C$2:$L$181, 10, FALSE) = 0, "", VLOOKUP($C57, Mapping!$C$2:$L$181, 10, FALSE)) -> Set to -1 by default if intra-reticle coordinates not available.
B58: Test site ID | C58: =IF(NOT(ISBLANK(B58)),_xlfn.CONCAT(A58,"[",B58,"]"),"") -> [Test site ID] | D58: =IF(VLOOKUP($C58, Mapping!$C$2:$L$181, 2, FALSE) = 0, "", VLOOKUP($C58, Mapping!$C$2:$L$181, 2, FALSE)) | E58: =IF(VLOOKUP($C58, Mapping!$C$2:$L$181, 3, FALSE) = 0, "", VLOOKUP($C58, Mapping!$C$2:$L$181, 3, FALSE)) -> PRR.SITE_NUM | F58: =IF(VLOOKUP($C58, Mapping!$C$2:$L$181, 4, FALSE) = 0, "", VLOOKUP($C58, Mapping!$C$2:$L$181, 4, FALSE)) -> Test site ID | G58: =IF(VLOOKUP($C58, Mapping!$C$2:$L$181, 6, FALSE) = 0, "", VLOOKUP($C58, Mapping!$C$2:$L$181, 6, FALSE)) -> test_site | H58: =IF(VLOOKUP($C58, Mapping!$C$2:$L$181, 7, FALSE) = 0, "", VLOOKUP($C58, Mapping!$C$2:$L$181, 7, FALSE)) -> res index | I58: =IF(VLOOKUP($C58, Mapping!$C$2:$L$181, 8, FALSE) = 0, "", VLOOKUP($C58, Mapping!$C$2:$L$181, 8, FALSE)) -> non-key | J58: =IF(VLOOKUP($C58, Mapping!$C$2:$L$181, 9, FALSE) = 0, "", VLOOKUP($C58, Mapping!$C$2:$L$181, 9, FALSE)) -> Integer | K58: =IF(VLOOKUP($C58, Mapping!$C$2:$L$181, 10, FALSE) = 0, "", VLOOKUP($C58, Mapping!$C$2:$L$181, 10, FALSE))
... B60: Lot Type | C60: =IF(NOT(ISBLANK(B60)),_xlfn.CONCAT(A60,"[",B60,"]"),"") -> [Lot Type] | D60: =IF(VLOOKUP($C60, Mapping!$C$2:$L$181, 2, FALSE) = 0, "", VLOOKUP($C60, Mapping!$C$2:$L$181, 2, FALSE)) -> #N/A | E60: =IF(VLOOKUP($C60, Mapping!$C$2:$L$181, 3, FALSE) = 0, "", VLOOKUP($C60, Mapping!$C$2:$L$181, 3, FALSE)) -> #N/A | F60: =IF(VLOOKUP($C60, Mapping!$C$2:$L$181, 4, FALSE) = 0, "", VLOOKUP($C60, Mapping!$C$2:$L$181, 4, FALSE)) -> #N/A | G60: =IF(VLOOKUP($C60, Mapping!$C$2:$L$181, 6, FALSE) = 0, "", VLOOKUP($C60, Mapping!$C$2:$L$181, 6, FALSE)) -> #N/A | H60: =IF(VLOOKUP($C60, Mapping!$C$2:$L$181, 7, FALSE) = 0, "", VLOOKUP($C60, Mapping!$C$2:$L$181, 7, FALSE)) -> #N/A | I60: =IF(VLOOKUP($C60, Mapping!$C$2:$L$181, 8, FALSE) = 0, "", VLOOKUP($C60, Mapping!$C$2:$L$181, 8, FALSE)) -> #N/A | J60: =IF(VLOOKUP($C60, Mapping!$C$2:$L$181, 9, FALSE) = 0, "", VLOOKUP($C60, Mapping!$C$2:$L$181, 9, FALSE)) -> #N/A | K60: =IF(VLOOKUP($C60, Mapping!$C$2:$L$181, 10, FALSE) = 0, "", VLOOKUP($C60, Mapping!$C$2:$L$181, 10, FALSE)) -> #N/A

Sheet 1-probe_parametric_lim-sxml
A1: SXML Element | B1: XML Attribute | C1: Whole Name | D1: Metadata | E1: STDF Attribute2 | F1: Name in Yield Metadata Standardization | G1: How to Populate | H1: Index Type | I1: Key/non-key | J1: Data Type | K1: Comment
A2: LotG/SourceLot/Lot | B2: Fab | C2: =IF(NOT(ISBLANK(B2)),_xlfn.CONCAT(A2,"[",B2,"]"),"") -> LotG/SourceLot/Lot[Fab] | D2: =IF(VLOOKUP($C2, Mapping!$C$2:$L$181, 2, FALSE) = 0, "", VLOOKUP($C2, Mapping!$C$2:$L$181, 2, FALSE)) -> Fab | E2: =IF(VLOOKUP($C2, Mapping!$C$2:$L$181, 3, FALSE) = 0, "", VLOOKUP($C2, Mapping!$C$2:$L$181, 3, FALSE)) | F2: =IF(VLOOKUP($C2, Mapping!$C$2:$L$181, 4, FALSE) = 0, "", VLOOKUP($C2, Mapping!$C$2:$L$181, 4, FALSE)) -> Source Fab | G2: =IF(VLOOKUP($C2, Mapping!$C$2:$L$181, 6, FALSE) = 0, "", VLOOKUP($C2, Mapping!$C$2:$L$181, 6, FALSE)) -> vDbFab | H2: =IF(VLOOKUP($C2, Mapping!$C$2:$L$181, 7, FALSE) = 0, "", VLOOKUP($C2, Mapping!$C$2:$L$181, 7, FALSE)) | I2: =IF(VLOOKUP($C2, Mapping!$C$2:$L$181, 8, FALSE) = 0, "", VLOOKUP($C2, Mapping!$C$2:$L$181, 8, FALSE)) | J2: =IF(VLOOKUP($C2, Mapping!$C$2:$L$181, 9, FALSE) = 0, "", VLOOKUP($C2, Mapping!$C$2:$L$181, 9, FALSE)) | K2: =IF(VLOOKUP($C2, Mapping!$C$2:$L$181, 10, FALSE) = 0, "", VLOOKUP($C2, Mapping!$C$2:$L$181, 10, FALSE))
A3: LotG/SourceLot/Lot | B3: LotClass | C3: =IF(NOT(ISBLANK(B3)),_xlfn.CONCAT(A3,"[",B3,"]"),"") -> LotG/SourceLot/Lot[LotClass] | D3: =IF(VLOOKUP($C3, Mapping!$C$2:$L$181, 2, FALSE) = 0, "", VLOOKUP($C3, Mapping!$C$2:$L$181, 2, FALSE)) -> LotClass | E3: =IF(VLOOKUP($C3, Mapping!$C$2:$L$181, 3, FALSE) = 0, "", VLOOKUP($C3, Mapping!$C$2:$L$181, 3, FALSE)) | F3: =IF(VLOOKUP($C3, Mapping!$C$2:$L$181, 4, FALSE) = 0, "", VLOOKUP($C3, Mapping!$C$2:$L$181, 4, FALSE)) -> Lot Class | G3: =IF(VLOOKUP($C3, Mapping!$C$2:$L$181, 6, FALSE) = 0, "", VLOOKUP($C3, Mapping!$C$2:$L$181, 6, FALSE)) -> vDbLotClass | H3: =IF(VLOOKUP($C3, Mapping!$C$2:$L$181, 7, FALSE) = 0, "", VLOOKUP($C3, Mapping!$C$2:$L$181, 7, FALSE)) -> lot class | I3: =IF(VLOOKUP($C3, Mapping!$C$2:$L$181, 8, FALSE) = 0, "", VLOOKUP($C3, Mapping!$C$2:$L$181, 8, FALSE)) | J3: =IF(VLOOKUP($C3, Mapping!$C$2:$L$181, 9, FALSE) = 0, "", VLOOKUP($C3, Mapping!$C$2:$L$181, 9, FALSE)) -> String | K3: =IF(VLOOKUP($C3, Mapping!$C$2:$L$181, 10, FALSE) = 0, "", VLOOKUP($C3, Mapping!$C$2:$L$181, 10, FALSE)) -> LotG or LTM; Type of lot Engineering/Production,…
A4: LotG/SourceLot/Lot | B4: LotNumber | C4: =IF(NOT(ISBLANK(B4)),_xlfn.CONCAT(A4,"[",B4,"]"),"") -> LotG/SourceLot/Lot[LotNumber] | D4: =IF(VLOOKUP($C4, Mapping!$C$2:$L$181, 2, FALSE) = 0, "", VLOOKUP($C4, Mapping!$C$2:$L$181, 2, FALSE)) -> SubconLotId | E4: =IF(VLOOKUP($C4, Mapping!$C$2:$L$181, 3, FALSE) = 0, "", VLOOKUP($C4, Mapping!$C$2:$L$181, 3, FALSE)) | F4: =IF(VLOOKUP($C4, Mapping!$C$2:$L$181, 4, FALSE) = 0, "", VLOOKUP($C4, Mapping!$C$2:$L$181, 4, FALSE)) -> Subcon lot id | G4: =IF(VLOOKUP($C4, Mapping!$C$2:$L$181, 6, FALSE) = 0, "", VLOOKUP($C4, Mapping!$C$2:$L$181, 6, FALSE)) -> DbMetaData("Subcon lot id", vvSubconLotId) | H4: =IF(VLOOKUP($C4, Mapping!$C$2:$L$181, 7, FALSE) = 0, "", VLOOKUP($C4, Mapping!$C$2:$L$181, 7, FALSE)) -> op_log linked index 26 | I4: =IF(VLOOKUP($C4, Mapping!$C$2:$L$181, 8, FALSE) = 0, "", VLOOKUP($C4, Mapping!$C$2:$L$181, 8, FALSE)) | J4: =IF(VLOOKUP($C4, Mapping!$C$2:$L$181, 9, FALSE) = 0, "", VLOOKUP($C4, Mapping!$C$2:$L$181, 9, FALSE)) | K4: =IF(VLOOKUP($C4, Mapping!$C$2:$L$181, 10, FALSE) = 0, "", VLOOKUP($C4, Mapping!$C$2:$L$181, 10, FALSE))
A5: LotG/SourceLot/Lot | B5: WaferPart | C5: =IF(NOT(ISBLANK(B5)),_xlfn.CONCAT(A5,"[",B5,"]"),"") -> LotG/SourceLot/Lot[WaferPart] | D5: =IF(VLOOKUP($C5, Mapping!$C$2:$L$181, 2, FALSE) = 0, "", VLOOKUP($C5, Mapping!$C$2:$L$181, 2, FALSE)) -> Product | E5: =IF(VLOOKUP($C5, Mapping!$C$2:$L$181, 3, FALSE) = 0, "", VLOOKUP($C5, Mapping!$C$2:$L$181, 3, FALSE)) | F5: =IF(VLOOKUP($C5, Mapping!$C$2:$L$181, 4, FALSE) = 0, "", VLOOKUP($C5, Mapping!$C$2:$L$181, 4, FALSE)) -> MES Product ID / Mfg part # | G5: =IF(VLOOKUP($C5, Mapping!$C$2:$L$181, 6, FALSE) = 0, "", VLOOKUP($C5, Mapping!$C$2:$L$181, 6, FALSE)) -> vDbProduct | H5: =IF(VLOOKUP($C5, Mapping!$C$2:$L$181, 7, FALSE) = 0, "", VLOOKUP($C5, Mapping!$C$2:$L$181, 7, FALSE)) | I5: =IF(VLOOKUP($C5, Mapping!$C$2:$L$181, 8, FALSE) = 0, "", VLOOKUP($C5, Mapping!$C$2:$L$181, 8, FALSE)) | J5: =IF(VLOOKUP($C5, Mapping!$C$2:$L$181, 9, FALSE) = 0, "", VLOOKUP($C5, Mapping!$C$2:$L$181, 9, FALSE)) | K5: =IF(VLOOKUP($C5, Mapping!$C$2:$L$181, 10, FALSE) = 0, "", VLOOKUP($C5, Mapping!$C$2:$L$181, 10, FALSE))
A6: LotG/SourceLot/Lot | B6: Bank | C6: =IF(NOT(ISBLANK(B6)),_xlfn.CONCAT(A6,"[",B6,"]"),"") -> LotG/SourceLot/Lot[Bank] | D6: =IF(VLOOKUP($C6, Mapping!$C$2:$L$181, 2, FALSE) = 0, "", VLOOKUP($C6, Mapping!$C$2:$L$181, 2, FALSE)) | E6: =IF(VLOOKUP($C6, Mapping!$C$2:$L$181, 3, FALSE) = 0, "", VLOOKUP($C6, Mapping!$C$2:$L$181, 3, FALSE)) | F6: =IF(VLOOKUP($C6, Mapping!$C$2:$L$181, 4, FALSE) = 0, "", VLOOKUP($C6, Mapping!$C$2:$L$181, 4, FALSE)) -> Bank Lot | G6: =IF(VLOOKUP($C6, Mapping!$C$2:$L$181, 6, FALSE) = 0, "", VLOOKUP($C6, Mapping!$C$2:$L$181, 6, FALSE)) | H6: =IF(VLOOKUP($C6, Mapping!$C$2:$L$181, 7, FALSE) = 0, "", VLOOKUP($C6, Mapping!$C$2:$L$181, 7, FALSE)) | I6: =IF(VLOOKUP($C6, Mapping!$C$2:$L$181, 8, FALSE) = 0, "", VLOOKUP($C6, Mapping!$C$2:$L$181, 8, FALSE)) | J6: =IF(VLOOKUP($C6, Mapping!$C$2:$L$181, 9, FALSE) = 0, "", VLOOKUP($C6, Mapping!$C$2:$L$181, 9, FALSE)) | K6: =IF(VLOOKUP($C6, Mapping!$C$2:$L$181, 10, FALSE) = 0, "", VLOOKUP($C6, Mapping!$C$2:$L$181, 10, FALSE))
A7: DataPort | B7: TestFacility | C7: =IF(NOT(ISBLANK(B7)),_xlfn.CONCAT(A7,"[",B7,"]"),"") -> DataPort[TestFacility] | D7: =IF(VLOOKUP($C7, Mapping!$C$2:$L$181, 2, FALSE) = 0, "", VLOOKUP($C7, Mapping!$C$2:$L$181, 2, FALSE)) -> TestFacility | E7: =IF(VLOOKUP($C7, Mapping!$C$2:$L$181, 3, FALSE) = 0, "", VLOOKUP($C7, Mapping!$C$2:$L$181, 3, FALSE)) | F7: =IF(VLOOKUP($C7, Mapping!$C$2:$L$181, 4, FALSE) = 0, "", VLOOKUP($C7, Mapping!$C$2:$L$181, 4, FALSE)) -> Test Facility | G7: =IF(VLOOKUP($C7, Mapping!$C$2:$L$181, 6, FALSE) = 0, "", VLOOKUP($C7, Mapping!$C$2:$L$181, 6, FALSE)) -> vDbEquip6 | H7: =IF(VLOOKUP($C7, Mapping!$C$2:$L$181, 7, FALSE) = 0, "", VLOOKUP($C7, Mapping!$C$2:$L$181, 7, FALSE)) -> Equip[6] | I7: =IF(VLOOKUP($C7, Mapping!$C$2:$L$181, 8, FALSE) = 0, "", VLOOKUP($C7, Mapping!$C$2:$L$181, 8, FALSE)) | J7: =IF(VLOOKUP($C7, Mapping!$C$2:$L$181, 9, FALSE) = 0, "", VLOOKUP($C7, Mapping!$C$2:$L$181, 9, FALSE)) | K7: =IF(VLOOKUP($C7, Mapping!$C$2:$L$181, 10, FALSE) = 0, "", VLOOKUP($C7, Mapping!$C$2:$L$181, 10, FALSE))
A8: File | B8: FileName | C8: =IF(NOT(ISBLANK(B8)),_xlfn.CONCAT(A8,"[",B8,"]"),"") -> File[FileName] | D8: =IF(VLOOKUP($C8, Mapping!$C$2:$L$181, 2, FALSE) = 0, "", VLOOKUP($C8, Mapping!$C$2:$L$181, 2, FALSE)) -> DataFileName | E8: =IF(VLOOKUP($C8, Mapping!$C$2:$L$181, 3, FALSE) = 0, "", VLOOKUP($C8, Mapping!$C$2:$L$181, 3, FALSE)) | F8: =IF(VLOOKUP($C8, Mapping!$C$2:$L$181, 4, FALSE) = 0, "", VLOOKUP($C8, Mapping!$C$2:$L$181, 4, FALSE)) -> Data File Name | G8: =IF(VLOOKUP($C8, Mapping!$C$2:$L$181, 6, FALSE) = 0, "", VLOOKUP($C8, Mapping!$C$2:$L$181, 6, FALSE)) -> DbMetaData("Data File Name", vFileName) | H8: =IF(VLOOKUP($C8, Mapping!$C$2:$L$181, 7, FALSE) = 0, "", VLOOKUP($C8, Mapping!$C$2:$L$181, 7, FALSE)) -> op_log linked index 3 | I8: =IF(VLOOKUP($C8, Mapping!$C$2:$L$181, 8, FALSE) = 0, "", VLOOKUP($C8, Mapping!$C$2:$L$181, 8, FALSE)) | J8: =IF(VLOOKUP($C8, Mapping!$C$2:$L$181, 9, FALSE) = 0, "", VLOOKUP($C8, Mapping!$C$2:$L$181, 9, FALSE)) | K8: =IF(VLOOKUP($C8, Mapping!$C$2:$L$181, 10, FALSE) = 0, "", VLOOKUP($C8, Mapping!$C$2:$L$181, 10, FALSE))
A9: File/Lot | B9: FinishTime | C9: =IF(NOT(ISBLANK(B9)),_xlfn.CONCAT(A9,"[",B9,"]"),"") -> File/Lot[FinishTime] | D9: =IF(VLOOKUP($C9, Mapping!$C$2:$L$181, 2, FALSE) = 0, "", VLOOKUP($C9, Mapping!$C$2:$L$181, 2, FALSE)) -> EndTime | E9: =IF(VLOOKUP($C9, Mapping!$C$2:$L$181, 3, FALSE) = 0, "", VLOOKUP($C9, Mapping!$C$2:$L$181, 3, FALSE)) -> MRR.FINISH_T | F9: =IF(VLOOKUP($C9, Mapping!$C$2:$L$181, 4, FALSE) = 0, "", VLOOKUP($C9, Mapping!$C$2:$L$181, 4, FALSE)) -> End Time | G9: =IF(VLOOKUP($C9, Mapping!$C$2:$L$181, 6, FALSE) = 0, "", VLOOKUP($C9, Mapping!$C$2:$L$181, 6, FALSE)) -> vDbEndTime | H9: =IF(VLOOKUP($C9, Mapping!$C$2:$L$181, 7, FALSE) = 0, "", VLOOKUP($C9, Mapping!$C$2:$L$181, 7, FALSE)) | I9: =IF(VLOOKUP($C9, Mapping!$C$2:$L$181, 8, FALSE) = 0, "", VLOOKUP($C9, Mapping!$C$2:$L$181, 8, FALSE)) | J9: =IF(VLOOKUP($C9, Mapping!$C$2:$L$181, 9, FALSE) = 0, "", VLOOKUP($C9, Mapping!$C$2:$L$181, 9, FALSE)) | K9: =IF(VLOOKUP($C9, Mapping!$C$2:$L$181, 10, FALSE) = 0, "", VLOOKUP($C9, Mapping!$C$2:$L$181, 10, FALSE))
A10: File/Lot | B10: JobName | C10: =IF(NOT(ISBLANK(B10)),_xlfn.CONCAT(A10,"[",B10,"]"),"") -> File/Lot[JobName] | D10: =IF(VLOOKUP($C10, Mapping!$C$2:$L$181, 2, FALSE) = 0, "", VLOOKUP($C10, Mapping!$C$2:$L$181, 2, FALSE)) -> Recipe | E10: =IF(VLOOKUP($C10, Mapping!$C$2:$L$181, 3, FALSE) = 0, "", VLOOKUP($C10, Mapping!$C$2:$L$181, 3, FALSE)) -> MIR.JOB_NAM | F10: =IF(VLOOKUP($C10, Mapping!$C$2:$L$181, 4, FALSE) = 0, "", VLOOKUP($C10, Mapping!$C$2:$L$181, 4, FALSE)) -> Test Program Name | G10: =IF(VLOOKUP($C10, Mapping!$C$2:$L$181, 6, FALSE) = 0, "", VLOOKUP($C10, Mapping!$C$2:$L$181, 6, FALSE)) -> vDbRecipe | H10: =IF(VLOOKUP($C10, Mapping!$C$2:$L$181, 7, FALSE) = 0, "", VLOOKUP($C10, Mapping!$C$2:$L$181, 7, FALSE)) | I10: =IF(VLOOKUP($C10, Mapping!$C$2:$L$181, 8, FALSE) = 0, "", VLOOKUP($C10, Mapping!$C$2:$L$181, 8, FALSE)) | J10: =IF(VLOOKUP($C10, Mapping!$C$2:$L$181, 9, FALSE) = 0, "", VLOOKUP($C10, Mapping!$C$2:$L$181, 9, FALSE)) | K10: =IF(VLOOKUP($C10, Mapping!$C$2:$L$181, 10, FALSE) = 0, "", VLOOKUP($C10, Mapping!$C$2:$L$181, 10, FALSE))
A11: File/Lot | B11: JobRevision | C11: =IF(NOT(ISBLANK(B11)),_xlfn.CONCAT(A11,"[",B11,"]"),"") -> File/Lot[JobRevision] | D11: =IF(VLOOKUP($C11, Mapping!$C$2:$L$181, 2, FALSE) = 0, "", VLOOKUP($C11, Mapping!$C$2:$L$181, 2, FALSE)) -> RecipeRevision | E11: =IF(VLOOKUP($C11, Mapping!$C$2:$L$181, 3, FALSE) = 0, "", VLOOKUP($C11, Mapping!$C$2:$L$181, 3, FALSE)) -> MIR.JOB_REV | F11: =IF(VLOOKUP($C11, Mapping!$C$2:$L$181, 4, FALSE) = 0, "", VLOOKUP($C11, Mapping!$C$2:$L$181, 4, FALSE)) -> Test Program Revision | G11: =IF(VLOOKUP($C11, Mapping!$C$2:$L$181, 6, FALSE) = 0, "", VLOOKUP($C11, Mapping!$C$2:$L$181, 6, FALSE)) -> vDbEquip5, vDbProgRev | H11: =IF(VLOOKUP($C11, Mapping!$C$2:$L$181, 7, FALSE) = 0, "", VLOOKUP($C11, Mapping!$C$2:$L$181, 7, FALSE)) -> Equip[5] | I11: =IF(VLOOKUP($C11, Mapping!$C$2:$L$181, 8, FALSE) = 0, "", VLOOKUP($C11, Mapping!$C$2:$L$181, 8, FALSE)) | J11: =IF(VLOOKUP($C11, Mapping!$C$2:$L$181, 9, FALSE) = 0, "", VLOOKUP($C11, Mapping!$C$2:$L$181, 9, FALSE)) | K11: =IF(VLOOKUP($C11, Mapping!$C$2:$L$181, 10, FALSE) = 0, "", VLOOKUP($C11, Mapping!$C$2:$L$181, 10, FALSE))
A12: File/Lot | B12: LotId | C12: =IF(NOT(ISBLANK(B12)),_xlfn.CONCAT(A12,"[",B12,"]"),"") -> File/Lot[LotId] | D12: =IF(VLOOKUP($C12, Mapping!$C$2:$L$181, 2, FALSE) = 0, "", VLOOKUP($C12, Mapping!$C$2:$L$181, 2, FALSE)) -> LotId | E12: =IF(VLOOKUP($C12, Mapping!$C$2:$L$181, 3, FALSE) = 0, "", VLOOKUP($C12, Mapping!$C$2:$L$181, 3, FALSE)) -> MIR.LOT_ID | F12: =IF(VLOOKUP($C12, Mapping!$C$2:$L$181, 4, FALSE) = 0, "", VLOOKUP($C12, Mapping!$C$2:$L$181, 4, FALSE)) -> Lot ID | G12: =IF(VLOOKUP($C12, Mapping!$C$2:$L$181, 6, FALSE) = 0, "", VLOOKUP($C12, Mapping!$C$2:$L$181, 6, FALSE)) -> vDbLot | H12: =IF(VLOOKUP($C12, Mapping!$C$2:$L$181, 7, FALSE) = 0, "", VLOOKUP($C12, Mapping!$C$2:$L$181, 7, FALSE)) | I12: =IF(VLOOKUP($C12, Mapping!$C$2:$L$181, 8, FALSE) = 0, "", VLOOKUP($C12, Mapping!$C$2:$L$181, 8, FALSE)) | J12: =IF(VLOOKUP($C12, Mapping!$C$2:$L$181, 9, FALSE) = 0, "", VLOOKUP($C12, Mapping!$C$2:$L$181, 9, FALSE)) | K12: =IF(VLOOKUP($C12, Mapping!$C$2:$L$181, 10, FALSE) = 0, "", VLOOKUP($C12, Mapping!$C$2:$L$181, 10, FALSE))
A13: File/Lot | B13: ModeCode | C13: =IF(NOT(ISBLANK(B13)),_xlfn.CONCAT(A13,"[",B13,"]"),"") -> File/Lot[ModeCode] | D13: =IF(VLOOKUP($C13, Mapping!$C$2:$L$181, 2, FALSE) = 0, "", VLOOKUP($C13, Mapping!$C$2:$L$181, 2, FALSE)) | E13: =IF(VLOOKUP($C13, Mapping!$C$2:$L$181, 3, FALSE) = 0, "", VLOOKUP($C13, Mapping!$C$2:$L$181, 3, FALSE)) -> MIR.MODE_COD | F13: =IF(VLOOKUP($C13, Mapping!$C$2:$L$181, 4, FALSE) = 0, "", VLOOKUP($C13, Mapping!$C$2:$L$181, 4, FALSE)) | G13: =IF(VLOOKUP($C13, Mapping!$C$2:$L$181, 6, FALSE) = 0, "", VLOOKUP($C13, Mapping!$C$2:$L$181, 6, FALSE)) | H13: =IF(VLOOKUP($C13, Mapping!$C$2:$L$181, 7, FALSE) = 0, "", VLOOKUP($C13, Mapping!$C$2:$L$181, 7, FALSE)) | I13: =IF(VLOOKUP($C13, Mapping!$C$2:$L$181, 8, FALSE) = 0, "", VLOOKUP($C13, Mapping!$C$2:$L$181, 8, FALSE)) | J13: =IF(VLOOKUP($C13, Mapping!$C$2:$L$181, 9, FALSE) = 0, "", VLOOKUP($C13, Mapping!$C$2:$L$181, 9, FALSE)) | K13: =IF(VLOOKUP($C13, Mapping!$C$2:$L$181, 10, FALSE) = 0, "", VLOOKUP($C13, Mapping!$C$2:$L$181, 10, FALSE))
... A33: File/Lot/Wafer/ParametricData/Unit | B33: Site | C33: =IF(NOT(ISBLANK(B33)),_xlfn.CONCAT(A33,"[",B33,"]"),"") -> File/Lot/Wafer/ParametricData/Unit[Site] | D33: =IF(VLOOKUP($C33, Mapping!$C$2:$L$181, 2, FALSE) = 0, "", VLOOKUP($C33, Mapping!$C$2:$L$181, 2, FALSE)) | E33: =IF(VLOOKUP($C33, Mapping!$C$2:$L$181, 3, FALSE) = 0, "", VLOOKUP($C33, Mapping!$C$2:$L$181, 3, FALSE)) | F33: =IF(VLOOKUP($C33, Mapping!$C$2:$L$181, 4, FALSE) = 0, "", VLOOKUP($C33, Mapping!$C$2:$L$181, 4, FALSE)) -> Test Site ID | G33: =IF(VLOOKUP($C33, Mapping!$C$2:$L$181, 6, FALSE) = 0, "", VLOOKUP($C33, Mapping!$C$2:$L$181, 6, FALSE)) -> TestSite (Index) | H33: =IF(VLOOKUP($C33, Mapping!$C$2:$L$181, 7, FALSE) = 0, "", VLOOKUP($C33, Mapping!$C$2:$L$181, 7, FALSE)) | I33: =IF(VLOOKUP($C33, Mapping!$C$2:$L$181, 8, FALSE) = 0, "", VLOOKUP($C33, Mapping!$C$2:$L$181, 8, FALSE)) | J33: =IF(VLOOKUP($C33, Mapping!$C$2:$L$181, 9, FALSE) = 0, "", VLOOKUP($C33, Mapping!$C$2:$L$181, 9, FALSE)) | K33: =IF(VLOOKUP($C33, Mapping!$C$2:$L$181, 10, FALSE) = 0, "", VLOOKUP($C33, Mapping!$C$2:$L$181, 10, FALSE))
B34: Program Group | C34: =IF(NOT(ISBLANK(B34)),_xlfn.CONCAT(A34,"[",B34,"]"),"") -> [Program Group] | D34: =IF(VLOOKUP($C34, Mapping!$C$2:$L$181, 2, FALSE) = 0, "", VLOOKUP($C34, Mapping!$C$2:$L$181, 2, FALSE)) -> ProgramGroup | E34: =IF(VLOOKUP($C34, Mapping!$C$2:$L$181, 3, FALSE) = 0, "", VLOOKUP($C34, Mapping!$C$2:$L$181, 3, FALSE)) | F34: =IF(VLOOKUP($C34, Mapping!$C$2:$L$181, 4, FALSE) = 0, "", VLOOKUP($C34, Mapping!$C$2:$L$181, 4, FALSE)) -> Program Group | G34: =IF(VLOOKUP($C34, Mapping!$C$2:$L$181, 6, FALSE) = 0, "", VLOOKUP($C34, Mapping!$C$2:$L$181, 6, FALSE)) -> vDbProgGroup | H34: =IF(VLOOKUP($C34, Mapping!$C$2:$L$181, 7, FALSE) = 0, "", VLOOKUP($C34, Mapping!$C$2:$L$181, 7, FALSE)) | I34: =IF(VLOOKUP($C34, Mapping!$C$2:$L$181, 8, FALSE) = 0, "", VLOOKUP($C34, Mapping!$C$2:$L$181, 8, FALSE)) | J34: =IF(VLOOKUP($C34, Mapping!$C$2:$L$181, 9, FALSE) = 0, "", VLOOKUP($C34, Mapping!$C$2:$L$181, 9, FALSE)) | K34: =IF(VLOOKUP($C34, Mapping!$C$2:$L$181, 10, FALSE) = 0, "", VLOOKUP($C34, Mapping!$C$2:$L$181, 10, FALSE)) -> Constant: "Probe Parametric"
B35: Area | C35: =IF(NOT(ISBLANK(B35)),_xlfn.CONCAT(A35,"[",B35,"]"),"") -> [Area] | D35: =IF(VLOOKUP($C35, Mapping!$C$2:$L$181, 2, FALSE) = 0, "", VLOOKUP($C35, Mapping!$C$2:$L$181, 2, FALSE)) | E35: =IF(VLOOKUP($C35, Mapping!$C$2:$L$181, 3, FALSE) = 0, "", VLOOKUP($C35, Mapping!$C$2:$L$181, 3, FALSE)) | F35: =IF(VLOOKUP($C35, Mapping!$C$2:$L$181, 4, FALSE) = 0, "", VLOOKUP($C35, Mapping!$C$2:$L$181, 4, FALSE)) -> Area | G35: =IF(VLOOKUP($C35, Mapping!$C$2:$L$181, 6, FALSE) = 0, "", VLOOKUP($C35, Mapping!$C$2:$L$181, 6, FALSE)) -> DbMetaData("Area", vArea) | H35: =IF(VLOOKUP($C35, Mapping!$C$2:$L$181, 7, FALSE) = 0, "", VLOOKUP($C35, Mapping!$C$2:$L$181, 7, FALSE)) -> op_log linked index 1 | I35: =IF(VLOOKUP($C35, Mapping!$C$2:$L$181, 8, FALSE) = 0, "", VLOOKUP($C35, Mapping!$C$2:$L$181, 8, FALSE)) | J35: =IF(VLOOKUP($C35, Mapping!$C$2:$L$181, 9, FALSE) = 0, "", VLOOKUP($C35, Mapping!$C$2:$L$181, 9, FALSE)) | K35: =IF(VLOOKUP($C35, Mapping!$C$2:$L$181, 10, FALSE) = 0, "", VLOOKUP($C35, Mapping!$C$2:$L$181, 10, FALSE)) -> Constant: "Probe"
